Watching for file changes with StatReloader
Watching for file changes with StatReloader
/home/admin1/yy/Smart360-app/api/v1/commonapp/serializers/sub_module.py changed, reloading.
Watching for file changes with StatReloader
/home/admin1/yy/Smart360-app/api/v1/userapp/serializers/user.py changed, reloading.
Watching for file changes with StatReloader
/home/admin1/yy/Smart360-app/api/v1/userapp/serializers/user.py changed, reloading.
Watching for file changes with StatReloader
Watching for file changes with StatReloader
/home/admin1/yy/Smart360-app/api/v1/commonapp/urls.py changed, reloading.
Watching for file changes with StatReloader
/home/admin1/yy/Smart360-app/api/api/urls.py changed, reloading.
Watching for file changes with StatReloader
Internal Server Error: /api/v1/registration/ba40504e-1220-4c23-80f7-95da2e9d4f85
Traceback (most recent call last):
  File "/home/admin1/Desktop/Environments/Bynry-360/lib/python3.6/site-packages/rest_framework/parsers.py", line 65, in parse
    return json.load(decoded_stream, parse_constant=parse_constant)
  File "/home/admin1/Desktop/Environments/Bynry-360/lib/python3.6/site-packages/rest_framework/utils/json.py", line 31, in load
    return json.load(*args, **kwargs)
  File "/usr/lib/python3.6/json/__init__.py", line 299, in load
    parse_constant=parse_constant, object_pairs_hook=object_pairs_hook, **kw)
  File "/usr/lib/python3.6/json/__init__.py", line 367, in loads
    return cls(**kw).decode(s)
  File "/usr/lib/python3.6/json/decoder.py", line 339, in decode
    obj, end = self.raw_decode(s, idx=_w(s, 0).end())
  File "/usr/lib/python3.6/json/decoder.py", line 355, in raw_decode
    obj, end = self.scan_once(s, idx)
json.decoder.JSONDecodeError: Expecting ',' delimiter: line 4 column 19 (char 74)

During handling of the above exception, another exception occurred:

Traceback (most recent call last):
  File "/home/admin1/yy/Smart360-app/api/v1/registration/views/registrations.py", line 134, in put
    if is_token_valid(request.data['token']):
  File "/home/admin1/Desktop/Environments/Bynry-360/lib/python3.6/site-packages/rest_framework/request.py", line 209, in data
    self._load_data_and_files()
  File "/home/admin1/Desktop/Environments/Bynry-360/lib/python3.6/site-packages/rest_framework/request.py", line 272, in _load_data_and_files
    self._data, self._files = self._parse()
  File "/home/admin1/Desktop/Environments/Bynry-360/lib/python3.6/site-packages/rest_framework/request.py", line 347, in _parse
    parsed = parser.parse(stream, media_type, self.parser_context)
  File "/home/admin1/Desktop/Environments/Bynry-360/lib/python3.6/site-packages/rest_framework/parsers.py", line 67, in parse
    raise ParseError('JSON parse error - %s' % str(exc))
rest_framework.exceptions.ParseError: JSON parse error - Expecting ',' delimiter: line 4 column 19 (char 74)

During handling of the above exception, another exception occurred:

Traceback (most recent call last):
  File "/home/admin1/Desktop/Environments/Bynry-360/lib/python3.6/site-packages/django/core/handlers/exception.py", line 34, in inner
    response = get_response(request)
  File "/home/admin1/Desktop/Environments/Bynry-360/lib/python3.6/site-packages/django/core/handlers/base.py", line 115, in _get_response
    response = self.process_exception_by_middleware(e, request)
  File "/home/admin1/Desktop/Environments/Bynry-360/lib/python3.6/site-packages/django/core/handlers/base.py", line 113, in _get_response
    response = wrapped_callback(request, *callback_args, **callback_kwargs)
  File "/home/admin1/Desktop/Environments/Bynry-360/lib/python3.6/site-packages/django/views/decorators/csrf.py", line 54, in wrapped_view
    return view_func(*args, **kwargs)
  File "/home/admin1/Desktop/Environments/Bynry-360/lib/python3.6/site-packages/django/views/generic/base.py", line 71, in view
    return self.dispatch(request, *args, **kwargs)
  File "/home/admin1/Desktop/Environments/Bynry-360/lib/python3.6/site-packages/rest_framework/views.py", line 505, in dispatch
    response = self.handle_exception(exc)
  File "/home/admin1/Desktop/Environments/Bynry-360/lib/python3.6/site-packages/rest_framework/views.py", line 465, in handle_exception
    self.raise_uncaught_exception(exc)
  File "/home/admin1/Desktop/Environments/Bynry-360/lib/python3.6/site-packages/rest_framework/views.py", line 476, in raise_uncaught_exception
    raise exc
  File "/home/admin1/Desktop/Environments/Bynry-360/lib/python3.6/site-packages/rest_framework/views.py", line 502, in dispatch
    response = handler(request, *args, **kwargs)
  File "/home/admin1/yy/Smart360-app/api/v1/registration/views/registrations.py", line 183, in put
    ERROR: str(traceback.print_exc(e))
  File "/usr/lib/python3.6/traceback.py", line 163, in print_exc
    print_exception(*sys.exc_info(), limit=limit, file=file, chain=chain)
  File "/usr/lib/python3.6/traceback.py", line 104, in print_exception
    type(value), value, tb, limit=limit).format(chain=chain):
  File "/usr/lib/python3.6/traceback.py", line 498, in __init__
    _seen=_seen)
  File "/usr/lib/python3.6/traceback.py", line 509, in __init__
    capture_locals=capture_locals)
  File "/usr/lib/python3.6/traceback.py", line 338, in extract
    if limit >= 0:
TypeError: '>=' not supported between instances of 'ParseError' and 'int'
"PUT /api/v1/registration/ba40504e-1220-4c23-80f7-95da2e9d4f85 HTTP/1.1" 500 20221
/home/admin1/yy/Smart360-app/api/v1/registration/views/registrations.py changed, reloading.
Watching for file changes with StatReloader
Internal Server Error: /api/v1/registration/ba40504e-1220-4c23-80f7-95da2e9d4f85
Traceback (most recent call last):
  File "/home/admin1/Desktop/Environments/Bynry-360/lib/python3.6/site-packages/rest_framework/parsers.py", line 65, in parse
    return json.load(decoded_stream, parse_constant=parse_constant)
  File "/home/admin1/Desktop/Environments/Bynry-360/lib/python3.6/site-packages/rest_framework/utils/json.py", line 31, in load
    return json.load(*args, **kwargs)
  File "/usr/lib/python3.6/json/__init__.py", line 299, in load
    parse_constant=parse_constant, object_pairs_hook=object_pairs_hook, **kw)
  File "/usr/lib/python3.6/json/__init__.py", line 367, in loads
    return cls(**kw).decode(s)
  File "/usr/lib/python3.6/json/decoder.py", line 339, in decode
    obj, end = self.raw_decode(s, idx=_w(s, 0).end())
  File "/usr/lib/python3.6/json/decoder.py", line 355, in raw_decode
    obj, end = self.scan_once(s, idx)
json.decoder.JSONDecodeError: Expecting ',' delimiter: line 4 column 19 (char 74)

During handling of the above exception, another exception occurred:

Traceback (most recent call last):
  File "/home/admin1/yy/Smart360-app/api/v1/registration/views/registrations.py", line 134, in put
    if is_token_valid(request.data['token']):
  File "/home/admin1/Desktop/Environments/Bynry-360/lib/python3.6/site-packages/rest_framework/request.py", line 209, in data
    self._load_data_and_files()
  File "/home/admin1/Desktop/Environments/Bynry-360/lib/python3.6/site-packages/rest_framework/request.py", line 272, in _load_data_and_files
    self._data, self._files = self._parse()
  File "/home/admin1/Desktop/Environments/Bynry-360/lib/python3.6/site-packages/rest_framework/request.py", line 347, in _parse
    parsed = parser.parse(stream, media_type, self.parser_context)
  File "/home/admin1/Desktop/Environments/Bynry-360/lib/python3.6/site-packages/rest_framework/parsers.py", line 67, in parse
    raise ParseError('JSON parse error - %s' % str(exc))
rest_framework.exceptions.ParseError: JSON parse error - Expecting ',' delimiter: line 4 column 19 (char 74)

During handling of the above exception, another exception occurred:

Traceback (most recent call last):
  File "/home/admin1/Desktop/Environments/Bynry-360/lib/python3.6/site-packages/django/core/handlers/exception.py", line 34, in inner
    response = get_response(request)
  File "/home/admin1/Desktop/Environments/Bynry-360/lib/python3.6/site-packages/django/core/handlers/base.py", line 115, in _get_response
    response = self.process_exception_by_middleware(e, request)
  File "/home/admin1/Desktop/Environments/Bynry-360/lib/python3.6/site-packages/django/core/handlers/base.py", line 113, in _get_response
    response = wrapped_callback(request, *callback_args, **callback_kwargs)
  File "/home/admin1/Desktop/Environments/Bynry-360/lib/python3.6/site-packages/django/views/decorators/csrf.py", line 54, in wrapped_view
    return view_func(*args, **kwargs)
  File "/home/admin1/Desktop/Environments/Bynry-360/lib/python3.6/site-packages/django/views/generic/base.py", line 71, in view
    return self.dispatch(request, *args, **kwargs)
  File "/home/admin1/Desktop/Environments/Bynry-360/lib/python3.6/site-packages/rest_framework/views.py", line 505, in dispatch
    response = self.handle_exception(exc)
  File "/home/admin1/Desktop/Environments/Bynry-360/lib/python3.6/site-packages/rest_framework/views.py", line 465, in handle_exception
    self.raise_uncaught_exception(exc)
  File "/home/admin1/Desktop/Environments/Bynry-360/lib/python3.6/site-packages/rest_framework/views.py", line 476, in raise_uncaught_exception
    raise exc
  File "/home/admin1/Desktop/Environments/Bynry-360/lib/python3.6/site-packages/rest_framework/views.py", line 502, in dispatch
    response = handler(request, *args, **kwargs)
  File "/home/admin1/yy/Smart360-app/api/v1/registration/views/registrations.py", line 184, in put
    ERROR: str(traceback.print_exc(e))
  File "/usr/lib/python3.6/traceback.py", line 163, in print_exc
    print_exception(*sys.exc_info(), limit=limit, file=file, chain=chain)
  File "/usr/lib/python3.6/traceback.py", line 104, in print_exception
    type(value), value, tb, limit=limit).format(chain=chain):
  File "/usr/lib/python3.6/traceback.py", line 498, in __init__
    _seen=_seen)
  File "/usr/lib/python3.6/traceback.py", line 509, in __init__
    capture_locals=capture_locals)
  File "/usr/lib/python3.6/traceback.py", line 338, in extract
    if limit >= 0:
TypeError: '>=' not supported between instances of 'ParseError' and 'int'
"PUT /api/v1/registration/ba40504e-1220-4c23-80f7-95da2e9d4f85 HTTP/1.1" 500 20221
Internal Server Error: /api/v1/registration/
Traceback (most recent call last):
  File "/home/admin1/Desktop/Environments/Bynry-360/lib/python3.6/site-packages/django/core/handlers/exception.py", line 34, in inner
    response = get_response(request)
  File "/home/admin1/Desktop/Environments/Bynry-360/lib/python3.6/site-packages/django/core/handlers/base.py", line 115, in _get_response
    response = self.process_exception_by_middleware(e, request)
  File "/home/admin1/Desktop/Environments/Bynry-360/lib/python3.6/site-packages/django/core/handlers/base.py", line 113, in _get_response
    response = wrapped_callback(request, *callback_args, **callback_kwargs)
  File "/home/admin1/Desktop/Environments/Bynry-360/lib/python3.6/site-packages/django/views/decorators/csrf.py", line 54, in wrapped_view
    return view_func(*args, **kwargs)
  File "/home/admin1/Desktop/Environments/Bynry-360/lib/python3.6/site-packages/django/views/generic/base.py", line 71, in view
    return self.dispatch(request, *args, **kwargs)
  File "/home/admin1/Desktop/Environments/Bynry-360/lib/python3.6/site-packages/rest_framework/views.py", line 505, in dispatch
    response = self.handle_exception(exc)
  File "/home/admin1/Desktop/Environments/Bynry-360/lib/python3.6/site-packages/rest_framework/views.py", line 465, in handle_exception
    self.raise_uncaught_exception(exc)
  File "/home/admin1/Desktop/Environments/Bynry-360/lib/python3.6/site-packages/rest_framework/views.py", line 476, in raise_uncaught_exception
    raise exc
  File "/home/admin1/Desktop/Environments/Bynry-360/lib/python3.6/site-packages/rest_framework/views.py", line 502, in dispatch
    response = handler(request, *args, **kwargs)
TypeError: put() missing 1 required positional argument: 'id_string'
"PUT /api/v1/registration/ HTTP/1.1" 500 17439
"GET /api/v1/registration/list HTTP/1.1" 200 988
Internal Server Error: /api/v1/registration/
Traceback (most recent call last):
  File "/home/admin1/Desktop/Environments/Bynry-360/lib/python3.6/site-packages/django/core/handlers/exception.py", line 34, in inner
    response = get_response(request)
  File "/home/admin1/Desktop/Environments/Bynry-360/lib/python3.6/site-packages/django/core/handlers/base.py", line 115, in _get_response
    response = self.process_exception_by_middleware(e, request)
  File "/home/admin1/Desktop/Environments/Bynry-360/lib/python3.6/site-packages/django/core/handlers/base.py", line 113, in _get_response
    response = wrapped_callback(request, *callback_args, **callback_kwargs)
  File "/home/admin1/Desktop/Environments/Bynry-360/lib/python3.6/site-packages/django/views/decorators/csrf.py", line 54, in wrapped_view
    return view_func(*args, **kwargs)
  File "/home/admin1/Desktop/Environments/Bynry-360/lib/python3.6/site-packages/django/views/generic/base.py", line 71, in view
    return self.dispatch(request, *args, **kwargs)
  File "/home/admin1/Desktop/Environments/Bynry-360/lib/python3.6/site-packages/rest_framework/views.py", line 505, in dispatch
    response = self.handle_exception(exc)
  File "/home/admin1/Desktop/Environments/Bynry-360/lib/python3.6/site-packages/rest_framework/views.py", line 465, in handle_exception
    self.raise_uncaught_exception(exc)
  File "/home/admin1/Desktop/Environments/Bynry-360/lib/python3.6/site-packages/rest_framework/views.py", line 476, in raise_uncaught_exception
    raise exc
  File "/home/admin1/Desktop/Environments/Bynry-360/lib/python3.6/site-packages/rest_framework/views.py", line 502, in dispatch
    response = handler(request, *args, **kwargs)
TypeError: put() missing 1 required positional argument: 'id_string'
"PUT /api/v1/registration/ HTTP/1.1" 500 17440
Internal Server Error: /api/v1/registration/ba40504e-1220-4c23-80f7-95da2e9d4f85
Traceback (most recent call last):
  File "/home/admin1/Desktop/Environments/Bynry-360/lib/python3.6/site-packages/rest_framework/parsers.py", line 65, in parse
    return json.load(decoded_stream, parse_constant=parse_constant)
  File "/home/admin1/Desktop/Environments/Bynry-360/lib/python3.6/site-packages/rest_framework/utils/json.py", line 31, in load
    return json.load(*args, **kwargs)
  File "/usr/lib/python3.6/json/__init__.py", line 299, in load
    parse_constant=parse_constant, object_pairs_hook=object_pairs_hook, **kw)
  File "/usr/lib/python3.6/json/__init__.py", line 367, in loads
    return cls(**kw).decode(s)
  File "/usr/lib/python3.6/json/decoder.py", line 339, in decode
    obj, end = self.raw_decode(s, idx=_w(s, 0).end())
  File "/usr/lib/python3.6/json/decoder.py", line 355, in raw_decode
    obj, end = self.scan_once(s, idx)
json.decoder.JSONDecodeError: Expecting ',' delimiter: line 4 column 19 (char 74)

During handling of the above exception, another exception occurred:

Traceback (most recent call last):
  File "/home/admin1/yy/Smart360-app/api/v1/registration/views/registrations.py", line 134, in put
    if is_token_valid(request.data['token']):
  File "/home/admin1/Desktop/Environments/Bynry-360/lib/python3.6/site-packages/rest_framework/request.py", line 209, in data
    self._load_data_and_files()
  File "/home/admin1/Desktop/Environments/Bynry-360/lib/python3.6/site-packages/rest_framework/request.py", line 272, in _load_data_and_files
    self._data, self._files = self._parse()
  File "/home/admin1/Desktop/Environments/Bynry-360/lib/python3.6/site-packages/rest_framework/request.py", line 347, in _parse
    parsed = parser.parse(stream, media_type, self.parser_context)
  File "/home/admin1/Desktop/Environments/Bynry-360/lib/python3.6/site-packages/rest_framework/parsers.py", line 67, in parse
    raise ParseError('JSON parse error - %s' % str(exc))
rest_framework.exceptions.ParseError: JSON parse error - Expecting ',' delimiter: line 4 column 19 (char 74)

During handling of the above exception, another exception occurred:

Traceback (most recent call last):
  File "/home/admin1/Desktop/Environments/Bynry-360/lib/python3.6/site-packages/django/core/handlers/exception.py", line 34, in inner
    response = get_response(request)
  File "/home/admin1/Desktop/Environments/Bynry-360/lib/python3.6/site-packages/django/core/handlers/base.py", line 115, in _get_response
    response = self.process_exception_by_middleware(e, request)
  File "/home/admin1/Desktop/Environments/Bynry-360/lib/python3.6/site-packages/django/core/handlers/base.py", line 113, in _get_response
    response = wrapped_callback(request, *callback_args, **callback_kwargs)
  File "/home/admin1/Desktop/Environments/Bynry-360/lib/python3.6/site-packages/django/views/decorators/csrf.py", line 54, in wrapped_view
    return view_func(*args, **kwargs)
  File "/home/admin1/Desktop/Environments/Bynry-360/lib/python3.6/site-packages/django/views/generic/base.py", line 71, in view
    return self.dispatch(request, *args, **kwargs)
  File "/home/admin1/Desktop/Environments/Bynry-360/lib/python3.6/site-packages/rest_framework/views.py", line 505, in dispatch
    response = self.handle_exception(exc)
  File "/home/admin1/Desktop/Environments/Bynry-360/lib/python3.6/site-packages/rest_framework/views.py", line 465, in handle_exception
    self.raise_uncaught_exception(exc)
  File "/home/admin1/Desktop/Environments/Bynry-360/lib/python3.6/site-packages/rest_framework/views.py", line 476, in raise_uncaught_exception
    raise exc
  File "/home/admin1/Desktop/Environments/Bynry-360/lib/python3.6/site-packages/rest_framework/views.py", line 502, in dispatch
    response = handler(request, *args, **kwargs)
  File "/home/admin1/yy/Smart360-app/api/v1/registration/views/registrations.py", line 184, in put
    ERROR: str(traceback.print_exc(e))
  File "/usr/lib/python3.6/traceback.py", line 163, in print_exc
    print_exception(*sys.exc_info(), limit=limit, file=file, chain=chain)
  File "/usr/lib/python3.6/traceback.py", line 104, in print_exception
    type(value), value, tb, limit=limit).format(chain=chain):
  File "/usr/lib/python3.6/traceback.py", line 498, in __init__
    _seen=_seen)
  File "/usr/lib/python3.6/traceback.py", line 509, in __init__
    capture_locals=capture_locals)
  File "/usr/lib/python3.6/traceback.py", line 338, in extract
    if limit >= 0:
TypeError: '>=' not supported between instances of 'ParseError' and 'int'
"PUT /api/v1/registration/ba40504e-1220-4c23-80f7-95da2e9d4f85 HTTP/1.1" 500 20222
/home/admin1/yy/Smart360-app/api/v1/registration/urls.py changed, reloading.
Watching for file changes with StatReloader
Internal Server Error: /api/v1/registration/ba40504e-1220-4c23-80f7-95da2e9d4f85
Traceback (most recent call last):
  File "/home/admin1/Desktop/Environments/Bynry-360/lib/python3.6/site-packages/rest_framework/parsers.py", line 65, in parse
    return json.load(decoded_stream, parse_constant=parse_constant)
  File "/home/admin1/Desktop/Environments/Bynry-360/lib/python3.6/site-packages/rest_framework/utils/json.py", line 31, in load
    return json.load(*args, **kwargs)
  File "/usr/lib/python3.6/json/__init__.py", line 299, in load
    parse_constant=parse_constant, object_pairs_hook=object_pairs_hook, **kw)
  File "/usr/lib/python3.6/json/__init__.py", line 367, in loads
    return cls(**kw).decode(s)
  File "/usr/lib/python3.6/json/decoder.py", line 339, in decode
    obj, end = self.raw_decode(s, idx=_w(s, 0).end())
  File "/usr/lib/python3.6/json/decoder.py", line 355, in raw_decode
    obj, end = self.scan_once(s, idx)
json.decoder.JSONDecodeError: Expecting ',' delimiter: line 4 column 19 (char 74)

During handling of the above exception, another exception occurred:

Traceback (most recent call last):
  File "/home/admin1/yy/Smart360-app/api/v1/registration/views/registrations.py", line 134, in put
    if is_token_valid(request.data['token']):
  File "/home/admin1/Desktop/Environments/Bynry-360/lib/python3.6/site-packages/rest_framework/request.py", line 209, in data
    self._load_data_and_files()
  File "/home/admin1/Desktop/Environments/Bynry-360/lib/python3.6/site-packages/rest_framework/request.py", line 272, in _load_data_and_files
    self._data, self._files = self._parse()
  File "/home/admin1/Desktop/Environments/Bynry-360/lib/python3.6/site-packages/rest_framework/request.py", line 347, in _parse
    parsed = parser.parse(stream, media_type, self.parser_context)
  File "/home/admin1/Desktop/Environments/Bynry-360/lib/python3.6/site-packages/rest_framework/parsers.py", line 67, in parse
    raise ParseError('JSON parse error - %s' % str(exc))
rest_framework.exceptions.ParseError: JSON parse error - Expecting ',' delimiter: line 4 column 19 (char 74)

During handling of the above exception, another exception occurred:

Traceback (most recent call last):
  File "/home/admin1/Desktop/Environments/Bynry-360/lib/python3.6/site-packages/django/core/handlers/exception.py", line 34, in inner
    response = get_response(request)
  File "/home/admin1/Desktop/Environments/Bynry-360/lib/python3.6/site-packages/django/core/handlers/base.py", line 115, in _get_response
    response = self.process_exception_by_middleware(e, request)
  File "/home/admin1/Desktop/Environments/Bynry-360/lib/python3.6/site-packages/django/core/handlers/base.py", line 113, in _get_response
    response = wrapped_callback(request, *callback_args, **callback_kwargs)
  File "/home/admin1/Desktop/Environments/Bynry-360/lib/python3.6/site-packages/django/views/decorators/csrf.py", line 54, in wrapped_view
    return view_func(*args, **kwargs)
  File "/home/admin1/Desktop/Environments/Bynry-360/lib/python3.6/site-packages/django/views/generic/base.py", line 71, in view
    return self.dispatch(request, *args, **kwargs)
  File "/home/admin1/Desktop/Environments/Bynry-360/lib/python3.6/site-packages/rest_framework/views.py", line 505, in dispatch
    response = self.handle_exception(exc)
  File "/home/admin1/Desktop/Environments/Bynry-360/lib/python3.6/site-packages/rest_framework/views.py", line 465, in handle_exception
    self.raise_uncaught_exception(exc)
  File "/home/admin1/Desktop/Environments/Bynry-360/lib/python3.6/site-packages/rest_framework/views.py", line 476, in raise_uncaught_exception
    raise exc
  File "/home/admin1/Desktop/Environments/Bynry-360/lib/python3.6/site-packages/rest_framework/views.py", line 502, in dispatch
    response = handler(request, *args, **kwargs)
  File "/home/admin1/yy/Smart360-app/api/v1/registration/views/registrations.py", line 184, in put
    ERROR: str(traceback.print_exc(e))
  File "/usr/lib/python3.6/traceback.py", line 163, in print_exc
    print_exception(*sys.exc_info(), limit=limit, file=file, chain=chain)
  File "/usr/lib/python3.6/traceback.py", line 104, in print_exception
    type(value), value, tb, limit=limit).format(chain=chain):
  File "/usr/lib/python3.6/traceback.py", line 498, in __init__
    _seen=_seen)
  File "/usr/lib/python3.6/traceback.py", line 509, in __init__
    capture_locals=capture_locals)
  File "/usr/lib/python3.6/traceback.py", line 338, in extract
    if limit >= 0:
TypeError: '>=' not supported between instances of 'ParseError' and 'int'
"PUT /api/v1/registration/ba40504e-1220-4c23-80f7-95da2e9d4f85 HTTP/1.1" 500 20222
"GET /api/v1/registration/ba40504e-1220-4c23-80f7-95da2e9d4f85 HTTP/1.1" 200 568
Internal Server Error: /api/v1/registration/ba40504e-1220-4c23-80f7-95da2e9d4f85
Traceback (most recent call last):
  File "/home/admin1/Desktop/Environments/Bynry-360/lib/python3.6/site-packages/rest_framework/parsers.py", line 65, in parse
    return json.load(decoded_stream, parse_constant=parse_constant)
  File "/home/admin1/Desktop/Environments/Bynry-360/lib/python3.6/site-packages/rest_framework/utils/json.py", line 31, in load
    return json.load(*args, **kwargs)
  File "/usr/lib/python3.6/json/__init__.py", line 299, in load
    parse_constant=parse_constant, object_pairs_hook=object_pairs_hook, **kw)
  File "/usr/lib/python3.6/json/__init__.py", line 367, in loads
    return cls(**kw).decode(s)
  File "/usr/lib/python3.6/json/decoder.py", line 339, in decode
    obj, end = self.raw_decode(s, idx=_w(s, 0).end())
  File "/usr/lib/python3.6/json/decoder.py", line 355, in raw_decode
    obj, end = self.scan_once(s, idx)
json.decoder.JSONDecodeError: Expecting ',' delimiter: line 4 column 19 (char 74)

During handling of the above exception, another exception occurred:

Traceback (most recent call last):
  File "/home/admin1/yy/Smart360-app/api/v1/registration/views/registrations.py", line 134, in put
    if is_token_valid(request.data['token']):
  File "/home/admin1/Desktop/Environments/Bynry-360/lib/python3.6/site-packages/rest_framework/request.py", line 209, in data
    self._load_data_and_files()
  File "/home/admin1/Desktop/Environments/Bynry-360/lib/python3.6/site-packages/rest_framework/request.py", line 272, in _load_data_and_files
    self._data, self._files = self._parse()
  File "/home/admin1/Desktop/Environments/Bynry-360/lib/python3.6/site-packages/rest_framework/request.py", line 347, in _parse
    parsed = parser.parse(stream, media_type, self.parser_context)
  File "/home/admin1/Desktop/Environments/Bynry-360/lib/python3.6/site-packages/rest_framework/parsers.py", line 67, in parse
    raise ParseError('JSON parse error - %s' % str(exc))
rest_framework.exceptions.ParseError: JSON parse error - Expecting ',' delimiter: line 4 column 19 (char 74)

During handling of the above exception, another exception occurred:

Traceback (most recent call last):
  File "/home/admin1/Desktop/Environments/Bynry-360/lib/python3.6/site-packages/django/core/handlers/exception.py", line 34, in inner
    response = get_response(request)
  File "/home/admin1/Desktop/Environments/Bynry-360/lib/python3.6/site-packages/django/core/handlers/base.py", line 115, in _get_response
    response = self.process_exception_by_middleware(e, request)
  File "/home/admin1/Desktop/Environments/Bynry-360/lib/python3.6/site-packages/django/core/handlers/base.py", line 113, in _get_response
    response = wrapped_callback(request, *callback_args, **callback_kwargs)
  File "/home/admin1/Desktop/Environments/Bynry-360/lib/python3.6/site-packages/django/views/decorators/csrf.py", line 54, in wrapped_view
    return view_func(*args, **kwargs)
  File "/home/admin1/Desktop/Environments/Bynry-360/lib/python3.6/site-packages/django/views/generic/base.py", line 71, in view
    return self.dispatch(request, *args, **kwargs)
  File "/home/admin1/Desktop/Environments/Bynry-360/lib/python3.6/site-packages/rest_framework/views.py", line 505, in dispatch
    response = self.handle_exception(exc)
  File "/home/admin1/Desktop/Environments/Bynry-360/lib/python3.6/site-packages/rest_framework/views.py", line 465, in handle_exception
    self.raise_uncaught_exception(exc)
  File "/home/admin1/Desktop/Environments/Bynry-360/lib/python3.6/site-packages/rest_framework/views.py", line 476, in raise_uncaught_exception
    raise exc
  File "/home/admin1/Desktop/Environments/Bynry-360/lib/python3.6/site-packages/rest_framework/views.py", line 502, in dispatch
    response = handler(request, *args, **kwargs)
  File "/home/admin1/yy/Smart360-app/api/v1/registration/views/registrations.py", line 184, in put
    ERROR: str(traceback.print_exc(e))
  File "/usr/lib/python3.6/traceback.py", line 163, in print_exc
    print_exception(*sys.exc_info(), limit=limit, file=file, chain=chain)
  File "/usr/lib/python3.6/traceback.py", line 104, in print_exception
    type(value), value, tb, limit=limit).format(chain=chain):
  File "/usr/lib/python3.6/traceback.py", line 498, in __init__
    _seen=_seen)
  File "/usr/lib/python3.6/traceback.py", line 509, in __init__
    capture_locals=capture_locals)
  File "/usr/lib/python3.6/traceback.py", line 338, in extract
    if limit >= 0:
TypeError: '>=' not supported between instances of 'ParseError' and 'int'
"PUT /api/v1/registration/ba40504e-1220-4c23-80f7-95da2e9d4f85 HTTP/1.1" 500 20222
Internal Server Error: /api/v1/registration/ba40504e-1220-4c23-80f7-95da2e9d4f85
Traceback (most recent call last):
  File "/home/admin1/Desktop/Environments/Bynry-360/lib/python3.6/site-packages/rest_framework/parsers.py", line 65, in parse
    return json.load(decoded_stream, parse_constant=parse_constant)
  File "/home/admin1/Desktop/Environments/Bynry-360/lib/python3.6/site-packages/rest_framework/utils/json.py", line 31, in load
    return json.load(*args, **kwargs)
  File "/usr/lib/python3.6/json/__init__.py", line 299, in load
    parse_constant=parse_constant, object_pairs_hook=object_pairs_hook, **kw)
  File "/usr/lib/python3.6/json/__init__.py", line 367, in loads
    return cls(**kw).decode(s)
  File "/usr/lib/python3.6/json/decoder.py", line 339, in decode
    obj, end = self.raw_decode(s, idx=_w(s, 0).end())
  File "/usr/lib/python3.6/json/decoder.py", line 355, in raw_decode
    obj, end = self.scan_once(s, idx)
json.decoder.JSONDecodeError: Expecting ',' delimiter: line 4 column 19 (char 74)

During handling of the above exception, another exception occurred:

Traceback (most recent call last):
  File "/home/admin1/yy/Smart360-app/api/v1/registration/views/registrations.py", line 134, in put
    if is_token_valid(request.data['token']):
  File "/home/admin1/Desktop/Environments/Bynry-360/lib/python3.6/site-packages/rest_framework/request.py", line 209, in data
    self._load_data_and_files()
  File "/home/admin1/Desktop/Environments/Bynry-360/lib/python3.6/site-packages/rest_framework/request.py", line 272, in _load_data_and_files
    self._data, self._files = self._parse()
  File "/home/admin1/Desktop/Environments/Bynry-360/lib/python3.6/site-packages/rest_framework/request.py", line 347, in _parse
    parsed = parser.parse(stream, media_type, self.parser_context)
  File "/home/admin1/Desktop/Environments/Bynry-360/lib/python3.6/site-packages/rest_framework/parsers.py", line 67, in parse
    raise ParseError('JSON parse error - %s' % str(exc))
rest_framework.exceptions.ParseError: JSON parse error - Expecting ',' delimiter: line 4 column 19 (char 74)

During handling of the above exception, another exception occurred:

Traceback (most recent call last):
  File "/home/admin1/Desktop/Environments/Bynry-360/lib/python3.6/site-packages/django/core/handlers/exception.py", line 34, in inner
    response = get_response(request)
  File "/home/admin1/Desktop/Environments/Bynry-360/lib/python3.6/site-packages/django/core/handlers/base.py", line 115, in _get_response
    response = self.process_exception_by_middleware(e, request)
  File "/home/admin1/Desktop/Environments/Bynry-360/lib/python3.6/site-packages/django/core/handlers/base.py", line 113, in _get_response
    response = wrapped_callback(request, *callback_args, **callback_kwargs)
  File "/home/admin1/Desktop/Environments/Bynry-360/lib/python3.6/site-packages/django/views/decorators/csrf.py", line 54, in wrapped_view
    return view_func(*args, **kwargs)
  File "/home/admin1/Desktop/Environments/Bynry-360/lib/python3.6/site-packages/django/views/generic/base.py", line 71, in view
    return self.dispatch(request, *args, **kwargs)
  File "/home/admin1/Desktop/Environments/Bynry-360/lib/python3.6/site-packages/rest_framework/views.py", line 505, in dispatch
    response = self.handle_exception(exc)
  File "/home/admin1/Desktop/Environments/Bynry-360/lib/python3.6/site-packages/rest_framework/views.py", line 465, in handle_exception
    self.raise_uncaught_exception(exc)
  File "/home/admin1/Desktop/Environments/Bynry-360/lib/python3.6/site-packages/rest_framework/views.py", line 476, in raise_uncaught_exception
    raise exc
  File "/home/admin1/Desktop/Environments/Bynry-360/lib/python3.6/site-packages/rest_framework/views.py", line 502, in dispatch
    response = handler(request, *args, **kwargs)
  File "/home/admin1/yy/Smart360-app/api/v1/registration/views/registrations.py", line 184, in put
    ERROR: str(traceback.print_exc(e))
  File "/usr/lib/python3.6/traceback.py", line 163, in print_exc
    print_exception(*sys.exc_info(), limit=limit, file=file, chain=chain)
  File "/usr/lib/python3.6/traceback.py", line 104, in print_exception
    type(value), value, tb, limit=limit).format(chain=chain):
  File "/usr/lib/python3.6/traceback.py", line 498, in __init__
    _seen=_seen)
  File "/usr/lib/python3.6/traceback.py", line 509, in __init__
    capture_locals=capture_locals)
  File "/usr/lib/python3.6/traceback.py", line 338, in extract
    if limit >= 0:
TypeError: '>=' not supported between instances of 'ParseError' and 'int'
"PUT /api/v1/registration/ba40504e-1220-4c23-80f7-95da2e9d4f85 HTTP/1.1" 500 20221
"GET /api/v1/registration/4d5e2355-80e1-4765-9a4f-f0fab5d24035 HTTP/1.1" 200 571
"GET /api/v1/registration/4d5e2355-80e1-4765-9a4f-f0fab5d24035 HTTP/1.1" 200 571
"GET /admin/registration/registration/ HTTP/1.1" 200 5113
"GET /admin/jsi18n/ HTTP/1.1" 200 3223
/home/admin1/yy/Smart360-app/api/v1/registration/views/registrations.py changed, reloading.
Watching for file changes with StatReloader
/home/admin1/yy/Smart360-app/api/v1/registration/views/registrations.py changed, reloading.
Watching for file changes with StatReloader
Bad Request: /api/v1/registration/ba40504e-1220-4c23-80f7-95da2e9d4f85
"PUT /api/v1/registration/ba40504e-1220-4c23-80f7-95da2e9d4f85 HTTP/1.1" 400 83
Bad Request: /api/v1/registration/ba40504e-1220-4c23-80f7-95da2e9d4f85
"PUT /api/v1/registration/ba40504e-1220-4c23-80f7-95da2e9d4f85 HTTP/1.1" 400 83
Bad Request: /api/v1/registration/ba40504e-1220-4c23-80f7-95da2e9d4f85
"PUT /api/v1/registration/ba40504e-1220-4c23-80f7-95da2e9d4f85 HTTP/1.1" 400 83
/home/admin1/yy/Smart360-app/api/v1/registration/views/registrations.py changed, reloading.
Watching for file changes with StatReloader
Internal Server Error: /api/v1/registration/ba40504e-1220-4c23-80f7-95da2e9d4f85
Traceback (most recent call last):
  File "/home/admin1/Desktop/Environments/Bynry-360/lib/python3.6/site-packages/rest_framework/parsers.py", line 65, in parse
    return json.load(decoded_stream, parse_constant=parse_constant)
  File "/home/admin1/Desktop/Environments/Bynry-360/lib/python3.6/site-packages/rest_framework/utils/json.py", line 31, in load
    return json.load(*args, **kwargs)
  File "/usr/lib/python3.6/json/__init__.py", line 299, in load
    parse_constant=parse_constant, object_pairs_hook=object_pairs_hook, **kw)
  File "/usr/lib/python3.6/json/__init__.py", line 367, in loads
    return cls(**kw).decode(s)
  File "/usr/lib/python3.6/json/decoder.py", line 339, in decode
    obj, end = self.raw_decode(s, idx=_w(s, 0).end())
  File "/usr/lib/python3.6/json/decoder.py", line 355, in raw_decode
    obj, end = self.scan_once(s, idx)
json.decoder.JSONDecodeError: Expecting ',' delimiter: line 4 column 19 (char 74)

During handling of the above exception, another exception occurred:

Traceback (most recent call last):
  File "/home/admin1/yy/Smart360-app/api/v1/registration/views/registrations.py", line 134, in put
    if is_token_valid(request.data['token']):
  File "/home/admin1/Desktop/Environments/Bynry-360/lib/python3.6/site-packages/rest_framework/request.py", line 209, in data
    self._load_data_and_files()
  File "/home/admin1/Desktop/Environments/Bynry-360/lib/python3.6/site-packages/rest_framework/request.py", line 272, in _load_data_and_files
    self._data, self._files = self._parse()
  File "/home/admin1/Desktop/Environments/Bynry-360/lib/python3.6/site-packages/rest_framework/request.py", line 347, in _parse
    parsed = parser.parse(stream, media_type, self.parser_context)
  File "/home/admin1/Desktop/Environments/Bynry-360/lib/python3.6/site-packages/rest_framework/parsers.py", line 67, in parse
    raise ParseError('JSON parse error - %s' % str(exc))
rest_framework.exceptions.ParseError: JSON parse error - Expecting ',' delimiter: line 4 column 19 (char 74)

During handling of the above exception, another exception occurred:

Traceback (most recent call last):
  File "/home/admin1/Desktop/Environments/Bynry-360/lib/python3.6/site-packages/django/core/handlers/exception.py", line 34, in inner
    response = get_response(request)
  File "/home/admin1/Desktop/Environments/Bynry-360/lib/python3.6/site-packages/django/core/handlers/base.py", line 115, in _get_response
    response = self.process_exception_by_middleware(e, request)
  File "/home/admin1/Desktop/Environments/Bynry-360/lib/python3.6/site-packages/django/core/handlers/base.py", line 113, in _get_response
    response = wrapped_callback(request, *callback_args, **callback_kwargs)
  File "/home/admin1/Desktop/Environments/Bynry-360/lib/python3.6/site-packages/django/views/decorators/csrf.py", line 54, in wrapped_view
    return view_func(*args, **kwargs)
  File "/home/admin1/Desktop/Environments/Bynry-360/lib/python3.6/site-packages/django/views/generic/base.py", line 71, in view
    return self.dispatch(request, *args, **kwargs)
  File "/home/admin1/Desktop/Environments/Bynry-360/lib/python3.6/site-packages/rest_framework/views.py", line 505, in dispatch
    response = self.handle_exception(exc)
  File "/home/admin1/Desktop/Environments/Bynry-360/lib/python3.6/site-packages/rest_framework/views.py", line 465, in handle_exception
    self.raise_uncaught_exception(exc)
  File "/home/admin1/Desktop/Environments/Bynry-360/lib/python3.6/site-packages/rest_framework/views.py", line 476, in raise_uncaught_exception
    raise exc
  File "/home/admin1/Desktop/Environments/Bynry-360/lib/python3.6/site-packages/rest_framework/views.py", line 502, in dispatch
    response = handler(request, *args, **kwargs)
  File "/home/admin1/yy/Smart360-app/api/v1/registration/views/registrations.py", line 183, in put
    ERROR: str(traceback.print_exc(e))
  File "/usr/lib/python3.6/traceback.py", line 163, in print_exc
    print_exception(*sys.exc_info(), limit=limit, file=file, chain=chain)
  File "/usr/lib/python3.6/traceback.py", line 104, in print_exception
    type(value), value, tb, limit=limit).format(chain=chain):
  File "/usr/lib/python3.6/traceback.py", line 498, in __init__
    _seen=_seen)
  File "/usr/lib/python3.6/traceback.py", line 509, in __init__
    capture_locals=capture_locals)
  File "/usr/lib/python3.6/traceback.py", line 338, in extract
    if limit >= 0:
TypeError: '>=' not supported between instances of 'ParseError' and 'int'
"PUT /api/v1/registration/ba40504e-1220-4c23-80f7-95da2e9d4f85 HTTP/1.1" 500 20221
Internal Server Error: /api/v1/registration/4d5e2355-80e1-4765-9a4f-f0fab5d24035
Traceback (most recent call last):
  File "/home/admin1/Desktop/Environments/Bynry-360/lib/python3.6/site-packages/rest_framework/parsers.py", line 65, in parse
    return json.load(decoded_stream, parse_constant=parse_constant)
  File "/home/admin1/Desktop/Environments/Bynry-360/lib/python3.6/site-packages/rest_framework/utils/json.py", line 31, in load
    return json.load(*args, **kwargs)
  File "/usr/lib/python3.6/json/__init__.py", line 299, in load
    parse_constant=parse_constant, object_pairs_hook=object_pairs_hook, **kw)
  File "/usr/lib/python3.6/json/__init__.py", line 367, in loads
    return cls(**kw).decode(s)
  File "/usr/lib/python3.6/json/decoder.py", line 339, in decode
    obj, end = self.raw_decode(s, idx=_w(s, 0).end())
  File "/usr/lib/python3.6/json/decoder.py", line 355, in raw_decode
    obj, end = self.scan_once(s, idx)
json.decoder.JSONDecodeError: Expecting ',' delimiter: line 4 column 19 (char 74)

During handling of the above exception, another exception occurred:

Traceback (most recent call last):
  File "/home/admin1/yy/Smart360-app/api/v1/registration/views/registrations.py", line 134, in put
    if is_token_valid(request.data['token']):
  File "/home/admin1/Desktop/Environments/Bynry-360/lib/python3.6/site-packages/rest_framework/request.py", line 209, in data
    self._load_data_and_files()
  File "/home/admin1/Desktop/Environments/Bynry-360/lib/python3.6/site-packages/rest_framework/request.py", line 272, in _load_data_and_files
    self._data, self._files = self._parse()
  File "/home/admin1/Desktop/Environments/Bynry-360/lib/python3.6/site-packages/rest_framework/request.py", line 347, in _parse
    parsed = parser.parse(stream, media_type, self.parser_context)
  File "/home/admin1/Desktop/Environments/Bynry-360/lib/python3.6/site-packages/rest_framework/parsers.py", line 67, in parse
    raise ParseError('JSON parse error - %s' % str(exc))
rest_framework.exceptions.ParseError: JSON parse error - Expecting ',' delimiter: line 4 column 19 (char 74)

During handling of the above exception, another exception occurred:

Traceback (most recent call last):
  File "/home/admin1/Desktop/Environments/Bynry-360/lib/python3.6/site-packages/django/core/handlers/exception.py", line 34, in inner
    response = get_response(request)
  File "/home/admin1/Desktop/Environments/Bynry-360/lib/python3.6/site-packages/django/core/handlers/base.py", line 115, in _get_response
    response = self.process_exception_by_middleware(e, request)
  File "/home/admin1/Desktop/Environments/Bynry-360/lib/python3.6/site-packages/django/core/handlers/base.py", line 113, in _get_response
    response = wrapped_callback(request, *callback_args, **callback_kwargs)
  File "/home/admin1/Desktop/Environments/Bynry-360/lib/python3.6/site-packages/django/views/decorators/csrf.py", line 54, in wrapped_view
    return view_func(*args, **kwargs)
  File "/home/admin1/Desktop/Environments/Bynry-360/lib/python3.6/site-packages/django/views/generic/base.py", line 71, in view
    return self.dispatch(request, *args, **kwargs)
  File "/home/admin1/Desktop/Environments/Bynry-360/lib/python3.6/site-packages/rest_framework/views.py", line 505, in dispatch
    response = self.handle_exception(exc)
  File "/home/admin1/Desktop/Environments/Bynry-360/lib/python3.6/site-packages/rest_framework/views.py", line 465, in handle_exception
    self.raise_uncaught_exception(exc)
  File "/home/admin1/Desktop/Environments/Bynry-360/lib/python3.6/site-packages/rest_framework/views.py", line 476, in raise_uncaught_exception
    raise exc
  File "/home/admin1/Desktop/Environments/Bynry-360/lib/python3.6/site-packages/rest_framework/views.py", line 502, in dispatch
    response = handler(request, *args, **kwargs)
  File "/home/admin1/yy/Smart360-app/api/v1/registration/views/registrations.py", line 183, in put
    ERROR: str(traceback.print_exc(e))
  File "/usr/lib/python3.6/traceback.py", line 163, in print_exc
    print_exception(*sys.exc_info(), limit=limit, file=file, chain=chain)
  File "/usr/lib/python3.6/traceback.py", line 104, in print_exception
    type(value), value, tb, limit=limit).format(chain=chain):
  File "/usr/lib/python3.6/traceback.py", line 498, in __init__
    _seen=_seen)
  File "/usr/lib/python3.6/traceback.py", line 509, in __init__
    capture_locals=capture_locals)
  File "/usr/lib/python3.6/traceback.py", line 338, in extract
    if limit >= 0:
TypeError: '>=' not supported between instances of 'ParseError' and 'int'
"PUT /api/v1/registration/4d5e2355-80e1-4765-9a4f-f0fab5d24035 HTTP/1.1" 500 20221
/home/admin1/yy/Smart360-app/api/v1/registration/views/registrations.py changed, reloading.
Watching for file changes with StatReloader
Internal Server Error: /api/v1/registration/4d5e2355-80e1-4765-9a4f-f0fab5d24035
Traceback (most recent call last):
  File "/home/admin1/Desktop/Environments/Bynry-360/lib/python3.6/site-packages/rest_framework/parsers.py", line 65, in parse
    return json.load(decoded_stream, parse_constant=parse_constant)
  File "/home/admin1/Desktop/Environments/Bynry-360/lib/python3.6/site-packages/rest_framework/utils/json.py", line 31, in load
    return json.load(*args, **kwargs)
  File "/usr/lib/python3.6/json/__init__.py", line 299, in load
    parse_constant=parse_constant, object_pairs_hook=object_pairs_hook, **kw)
  File "/usr/lib/python3.6/json/__init__.py", line 367, in loads
    return cls(**kw).decode(s)
  File "/usr/lib/python3.6/json/decoder.py", line 339, in decode
    obj, end = self.raw_decode(s, idx=_w(s, 0).end())
  File "/usr/lib/python3.6/json/decoder.py", line 355, in raw_decode
    obj, end = self.scan_once(s, idx)
json.decoder.JSONDecodeError: Expecting ',' delimiter: line 4 column 19 (char 74)

During handling of the above exception, another exception occurred:

Traceback (most recent call last):
  File "/home/admin1/yy/Smart360-app/api/v1/registration/views/registrations.py", line 153, in put
    serializer = RegistrationSerializer(data=request.data)
  File "/home/admin1/Desktop/Environments/Bynry-360/lib/python3.6/site-packages/rest_framework/request.py", line 209, in data
    self._load_data_and_files()
  File "/home/admin1/Desktop/Environments/Bynry-360/lib/python3.6/site-packages/rest_framework/request.py", line 272, in _load_data_and_files
    self._data, self._files = self._parse()
  File "/home/admin1/Desktop/Environments/Bynry-360/lib/python3.6/site-packages/rest_framework/request.py", line 347, in _parse
    parsed = parser.parse(stream, media_type, self.parser_context)
  File "/home/admin1/Desktop/Environments/Bynry-360/lib/python3.6/site-packages/rest_framework/parsers.py", line 67, in parse
    raise ParseError('JSON parse error - %s' % str(exc))
rest_framework.exceptions.ParseError: JSON parse error - Expecting ',' delimiter: line 4 column 19 (char 74)

During handling of the above exception, another exception occurred:

Traceback (most recent call last):
  File "/home/admin1/Desktop/Environments/Bynry-360/lib/python3.6/site-packages/django/core/handlers/exception.py", line 34, in inner
    response = get_response(request)
  File "/home/admin1/Desktop/Environments/Bynry-360/lib/python3.6/site-packages/django/core/handlers/base.py", line 115, in _get_response
    response = self.process_exception_by_middleware(e, request)
  File "/home/admin1/Desktop/Environments/Bynry-360/lib/python3.6/site-packages/django/core/handlers/base.py", line 113, in _get_response
    response = wrapped_callback(request, *callback_args, **callback_kwargs)
  File "/home/admin1/Desktop/Environments/Bynry-360/lib/python3.6/site-packages/django/views/decorators/csrf.py", line 54, in wrapped_view
    return view_func(*args, **kwargs)
  File "/home/admin1/Desktop/Environments/Bynry-360/lib/python3.6/site-packages/django/views/generic/base.py", line 71, in view
    return self.dispatch(request, *args, **kwargs)
  File "/home/admin1/Desktop/Environments/Bynry-360/lib/python3.6/site-packages/rest_framework/views.py", line 505, in dispatch
    response = self.handle_exception(exc)
  File "/home/admin1/Desktop/Environments/Bynry-360/lib/python3.6/site-packages/rest_framework/views.py", line 465, in handle_exception
    self.raise_uncaught_exception(exc)
  File "/home/admin1/Desktop/Environments/Bynry-360/lib/python3.6/site-packages/rest_framework/views.py", line 476, in raise_uncaught_exception
    raise exc
  File "/home/admin1/Desktop/Environments/Bynry-360/lib/python3.6/site-packages/rest_framework/views.py", line 502, in dispatch
    response = handler(request, *args, **kwargs)
  File "/home/admin1/yy/Smart360-app/api/v1/registration/views/registrations.py", line 183, in put
    ERROR: str(traceback.print_exc(e))
  File "/usr/lib/python3.6/traceback.py", line 163, in print_exc
    print_exception(*sys.exc_info(), limit=limit, file=file, chain=chain)
  File "/usr/lib/python3.6/traceback.py", line 104, in print_exception
    type(value), value, tb, limit=limit).format(chain=chain):
  File "/usr/lib/python3.6/traceback.py", line 498, in __init__
    _seen=_seen)
  File "/usr/lib/python3.6/traceback.py", line 509, in __init__
    capture_locals=capture_locals)
  File "/usr/lib/python3.6/traceback.py", line 338, in extract
    if limit >= 0:
TypeError: '>=' not supported between instances of 'ParseError' and 'int'
"PUT /api/v1/registration/4d5e2355-80e1-4765-9a4f-f0fab5d24035 HTTP/1.1" 500 20234
/home/admin1/yy/Smart360-app/api/v1/registration/views/registrations.py changed, reloading.
Watching for file changes with StatReloader
/home/admin1/yy/Smart360-app/api/v1/registration/views/registrations.py changed, reloading.
Watching for file changes with StatReloader
Bad Request: /api/v1/registration/4d5e2355-80e1-4765-9a4f-f0fab5d24035
"PUT /api/v1/registration/4d5e2355-80e1-4765-9a4f-f0fab5d24035 HTTP/1.1" 400 83
Internal Server Error: /api/v1/registration/4d5e2355-80e1-4765-9a4f-f0fab5d24035
Traceback (most recent call last):
  File "/home/admin1/yy/Smart360-app/api/v1/registration/views/registrations.py", line 156, in put
    registration_obj = serializer.update(registration_obj,serializer.validated_data, user)
  File "/home/admin1/yy/Smart360-app/api/v1/registration/serializers/registration.py", line 102, in update
    registration_obj.save()
  File "/home/admin1/Desktop/Environments/Bynry-360/lib/python3.6/site-packages/django/db/models/base.py", line 746, in save
    force_update=force_update, update_fields=update_fields)
  File "/home/admin1/Desktop/Environments/Bynry-360/lib/python3.6/site-packages/django/db/models/base.py", line 784, in save_base
    force_update, using, update_fields,
  File "/home/admin1/Desktop/Environments/Bynry-360/lib/python3.6/site-packages/django/db/models/base.py", line 865, in _save_table
    forced_update)
  File "/home/admin1/Desktop/Environments/Bynry-360/lib/python3.6/site-packages/django/db/models/base.py", line 917, in _do_update
    return filtered._update(values) > 0
  File "/home/admin1/Desktop/Environments/Bynry-360/lib/python3.6/site-packages/django/db/models/query.py", line 771, in _update
    return query.get_compiler(self.db).execute_sql(CURSOR)
  File "/home/admin1/Desktop/Environments/Bynry-360/lib/python3.6/site-packages/django/db/models/sql/compiler.py", line 1492, in execute_sql
    cursor = super().execute_sql(result_type)
  File "/home/admin1/Desktop/Environments/Bynry-360/lib/python3.6/site-packages/django/db/models/sql/compiler.py", line 1131, in execute_sql
    sql, params = self.as_sql()
  File "/home/admin1/Desktop/Environments/Bynry-360/lib/python3.6/site-packages/django/db/models/sql/compiler.py", line 1455, in as_sql
    % (field, val, field.__class__.__name__)
TypeError: Tried to update field registration.Registration.updated_by with a model instance, <UserDetail: rohan>. Use a value compatible with BigIntegerField.

During handling of the above exception, another exception occurred:

Traceback (most recent call last):
  File "/home/admin1/Desktop/Environments/Bynry-360/lib/python3.6/site-packages/django/core/handlers/exception.py", line 34, in inner
    response = get_response(request)
  File "/home/admin1/Desktop/Environments/Bynry-360/lib/python3.6/site-packages/django/core/handlers/base.py", line 115, in _get_response
    response = self.process_exception_by_middleware(e, request)
  File "/home/admin1/Desktop/Environments/Bynry-360/lib/python3.6/site-packages/django/core/handlers/base.py", line 113, in _get_response
    response = wrapped_callback(request, *callback_args, **callback_kwargs)
  File "/home/admin1/Desktop/Environments/Bynry-360/lib/python3.6/site-packages/django/views/decorators/csrf.py", line 54, in wrapped_view
    return view_func(*args, **kwargs)
  File "/home/admin1/Desktop/Environments/Bynry-360/lib/python3.6/site-packages/django/views/generic/base.py", line 71, in view
    return self.dispatch(request, *args, **kwargs)
  File "/home/admin1/Desktop/Environments/Bynry-360/lib/python3.6/site-packages/rest_framework/views.py", line 505, in dispatch
    response = self.handle_exception(exc)
  File "/home/admin1/Desktop/Environments/Bynry-360/lib/python3.6/site-packages/rest_framework/views.py", line 465, in handle_exception
    self.raise_uncaught_exception(exc)
  File "/home/admin1/Desktop/Environments/Bynry-360/lib/python3.6/site-packages/rest_framework/views.py", line 476, in raise_uncaught_exception
    raise exc
  File "/home/admin1/Desktop/Environments/Bynry-360/lib/python3.6/site-packages/rest_framework/views.py", line 502, in dispatch
    response = handler(request, *args, **kwargs)
  File "/home/admin1/yy/Smart360-app/api/v1/registration/views/registrations.py", line 184, in put
    ERROR: str(traceback.print_exc(e))
  File "/usr/lib/python3.6/traceback.py", line 163, in print_exc
    print_exception(*sys.exc_info(), limit=limit, file=file, chain=chain)
  File "/usr/lib/python3.6/traceback.py", line 104, in print_exception
    type(value), value, tb, limit=limit).format(chain=chain):
  File "/usr/lib/python3.6/traceback.py", line 509, in __init__
    capture_locals=capture_locals)
  File "/usr/lib/python3.6/traceback.py", line 338, in extract
    if limit >= 0:
TypeError: '>=' not supported between instances of 'TypeError' and 'int'
"PUT /api/v1/registration/4d5e2355-80e1-4765-9a4f-f0fab5d24035 HTTP/1.1" 500 20132
Internal Server Error: /api/v1/registration/4d5e2355-80e1-4765-9a4f-f0fab5d24035
Traceback (most recent call last):
  File "/home/admin1/yy/Smart360-app/api/v1/registration/views/registrations.py", line 156, in put
    registration_obj = serializer.update(registration_obj,serializer.validated_data, user)
  File "/home/admin1/yy/Smart360-app/api/v1/registration/serializers/registration.py", line 102, in update
    registration_obj.save()
  File "/home/admin1/Desktop/Environments/Bynry-360/lib/python3.6/site-packages/django/db/models/base.py", line 746, in save
    force_update=force_update, update_fields=update_fields)
  File "/home/admin1/Desktop/Environments/Bynry-360/lib/python3.6/site-packages/django/db/models/base.py", line 784, in save_base
    force_update, using, update_fields,
  File "/home/admin1/Desktop/Environments/Bynry-360/lib/python3.6/site-packages/django/db/models/base.py", line 865, in _save_table
    forced_update)
  File "/home/admin1/Desktop/Environments/Bynry-360/lib/python3.6/site-packages/django/db/models/base.py", line 917, in _do_update
    return filtered._update(values) > 0
  File "/home/admin1/Desktop/Environments/Bynry-360/lib/python3.6/site-packages/django/db/models/query.py", line 771, in _update
    return query.get_compiler(self.db).execute_sql(CURSOR)
  File "/home/admin1/Desktop/Environments/Bynry-360/lib/python3.6/site-packages/django/db/models/sql/compiler.py", line 1492, in execute_sql
    cursor = super().execute_sql(result_type)
  File "/home/admin1/Desktop/Environments/Bynry-360/lib/python3.6/site-packages/django/db/models/sql/compiler.py", line 1131, in execute_sql
    sql, params = self.as_sql()
  File "/home/admin1/Desktop/Environments/Bynry-360/lib/python3.6/site-packages/django/db/models/sql/compiler.py", line 1455, in as_sql
    % (field, val, field.__class__.__name__)
TypeError: Tried to update field registration.Registration.updated_by with a model instance, <UserDetail: rohan>. Use a value compatible with BigIntegerField.

During handling of the above exception, another exception occurred:

Traceback (most recent call last):
  File "/home/admin1/Desktop/Environments/Bynry-360/lib/python3.6/site-packages/django/core/handlers/exception.py", line 34, in inner
    response = get_response(request)
  File "/home/admin1/Desktop/Environments/Bynry-360/lib/python3.6/site-packages/django/core/handlers/base.py", line 115, in _get_response
    response = self.process_exception_by_middleware(e, request)
  File "/home/admin1/Desktop/Environments/Bynry-360/lib/python3.6/site-packages/django/core/handlers/base.py", line 113, in _get_response
    response = wrapped_callback(request, *callback_args, **callback_kwargs)
  File "/home/admin1/Desktop/Environments/Bynry-360/lib/python3.6/site-packages/django/views/decorators/csrf.py", line 54, in wrapped_view
    return view_func(*args, **kwargs)
  File "/home/admin1/Desktop/Environments/Bynry-360/lib/python3.6/site-packages/django/views/generic/base.py", line 71, in view
    return self.dispatch(request, *args, **kwargs)
  File "/home/admin1/Desktop/Environments/Bynry-360/lib/python3.6/site-packages/rest_framework/views.py", line 505, in dispatch
    response = self.handle_exception(exc)
  File "/home/admin1/Desktop/Environments/Bynry-360/lib/python3.6/site-packages/rest_framework/views.py", line 465, in handle_exception
    self.raise_uncaught_exception(exc)
  File "/home/admin1/Desktop/Environments/Bynry-360/lib/python3.6/site-packages/rest_framework/views.py", line 476, in raise_uncaught_exception
    raise exc
  File "/home/admin1/Desktop/Environments/Bynry-360/lib/python3.6/site-packages/rest_framework/views.py", line 502, in dispatch
    response = handler(request, *args, **kwargs)
  File "/home/admin1/yy/Smart360-app/api/v1/registration/views/registrations.py", line 184, in put
    ERROR: str(traceback.print_exc(e))
  File "/usr/lib/python3.6/traceback.py", line 163, in print_exc
    print_exception(*sys.exc_info(), limit=limit, file=file, chain=chain)
  File "/usr/lib/python3.6/traceback.py", line 104, in print_exception
    type(value), value, tb, limit=limit).format(chain=chain):
  File "/usr/lib/python3.6/traceback.py", line 509, in __init__
    capture_locals=capture_locals)
  File "/usr/lib/python3.6/traceback.py", line 338, in extract
    if limit >= 0:
TypeError: '>=' not supported between instances of 'TypeError' and 'int'
"PUT /api/v1/registration/4d5e2355-80e1-4765-9a4f-f0fab5d24035 HTTP/1.1" 500 20132
/home/admin1/yy/Smart360-app/api/v1/registration/views/registrations.py changed, reloading.
Watching for file changes with StatReloader
/home/admin1/yy/Smart360-app/api/v1/registration/views/registrations.py changed, reloading.
Watching for file changes with StatReloader
Internal Server Error: /api/v1/registration/4d5e2355-80e1-4765-9a4f-f0fab5d24035
Traceback (most recent call last):
  File "/home/admin1/yy/Smart360-app/api/v1/registration/views/registrations.py", line 156, in put
    registration_obj = serializer.update(registration_obj,serializer.validated_data, user)
  File "/home/admin1/yy/Smart360-app/api/v1/registration/serializers/registration.py", line 102, in update
    registration_obj.save()
  File "/home/admin1/Desktop/Environments/Bynry-360/lib/python3.6/site-packages/django/db/models/base.py", line 746, in save
    force_update=force_update, update_fields=update_fields)
  File "/home/admin1/Desktop/Environments/Bynry-360/lib/python3.6/site-packages/django/db/models/base.py", line 784, in save_base
    force_update, using, update_fields,
  File "/home/admin1/Desktop/Environments/Bynry-360/lib/python3.6/site-packages/django/db/models/base.py", line 865, in _save_table
    forced_update)
  File "/home/admin1/Desktop/Environments/Bynry-360/lib/python3.6/site-packages/django/db/models/base.py", line 917, in _do_update
    return filtered._update(values) > 0
  File "/home/admin1/Desktop/Environments/Bynry-360/lib/python3.6/site-packages/django/db/models/query.py", line 771, in _update
    return query.get_compiler(self.db).execute_sql(CURSOR)
  File "/home/admin1/Desktop/Environments/Bynry-360/lib/python3.6/site-packages/django/db/models/sql/compiler.py", line 1492, in execute_sql
    cursor = super().execute_sql(result_type)
  File "/home/admin1/Desktop/Environments/Bynry-360/lib/python3.6/site-packages/django/db/models/sql/compiler.py", line 1131, in execute_sql
    sql, params = self.as_sql()
  File "/home/admin1/Desktop/Environments/Bynry-360/lib/python3.6/site-packages/django/db/models/sql/compiler.py", line 1455, in as_sql
    % (field, val, field.__class__.__name__)
TypeError: Tried to update field registration.Registration.updated_by with a model instance, <UserDetail: rohan>. Use a value compatible with BigIntegerField.

During handling of the above exception, another exception occurred:

Traceback (most recent call last):
  File "/home/admin1/Desktop/Environments/Bynry-360/lib/python3.6/site-packages/django/core/handlers/exception.py", line 34, in inner
    response = get_response(request)
  File "/home/admin1/Desktop/Environments/Bynry-360/lib/python3.6/site-packages/django/core/handlers/base.py", line 115, in _get_response
    response = self.process_exception_by_middleware(e, request)
  File "/home/admin1/Desktop/Environments/Bynry-360/lib/python3.6/site-packages/django/core/handlers/base.py", line 113, in _get_response
    response = wrapped_callback(request, *callback_args, **callback_kwargs)
  File "/home/admin1/Desktop/Environments/Bynry-360/lib/python3.6/site-packages/django/views/decorators/csrf.py", line 54, in wrapped_view
    return view_func(*args, **kwargs)
  File "/home/admin1/Desktop/Environments/Bynry-360/lib/python3.6/site-packages/django/views/generic/base.py", line 71, in view
    return self.dispatch(request, *args, **kwargs)
  File "/home/admin1/Desktop/Environments/Bynry-360/lib/python3.6/site-packages/rest_framework/views.py", line 505, in dispatch
    response = self.handle_exception(exc)
  File "/home/admin1/Desktop/Environments/Bynry-360/lib/python3.6/site-packages/rest_framework/views.py", line 465, in handle_exception
    self.raise_uncaught_exception(exc)
  File "/home/admin1/Desktop/Environments/Bynry-360/lib/python3.6/site-packages/rest_framework/views.py", line 476, in raise_uncaught_exception
    raise exc
  File "/home/admin1/Desktop/Environments/Bynry-360/lib/python3.6/site-packages/rest_framework/views.py", line 502, in dispatch
    response = handler(request, *args, **kwargs)
  File "/home/admin1/yy/Smart360-app/api/v1/registration/views/registrations.py", line 184, in put
    ERROR: str(traceback.print_exc(e))
  File "/usr/lib/python3.6/traceback.py", line 163, in print_exc
    print_exception(*sys.exc_info(), limit=limit, file=file, chain=chain)
  File "/usr/lib/python3.6/traceback.py", line 104, in print_exception
    type(value), value, tb, limit=limit).format(chain=chain):
  File "/usr/lib/python3.6/traceback.py", line 509, in __init__
    capture_locals=capture_locals)
  File "/usr/lib/python3.6/traceback.py", line 338, in extract
    if limit >= 0:
TypeError: '>=' not supported between instances of 'TypeError' and 'int'
"PUT /api/v1/registration/4d5e2355-80e1-4765-9a4f-f0fab5d24035 HTTP/1.1" 500 20132
/home/admin1/yy/Smart360-app/api/v1/registration/views/registrations.py changed, reloading.
Watching for file changes with StatReloader
Internal Server Error: /api/v1/registration/4d5e2355-80e1-4765-9a4f-f0fab5d24035
Traceback (most recent call last):
  File "/home/admin1/yy/Smart360-app/api/v1/registration/views/registrations.py", line 156, in put
    registration_obj = serializer.update(registration_obj,serializer.validated_data, user)
  File "/home/admin1/yy/Smart360-app/api/v1/registration/serializers/registration.py", line 102, in update
    registration_obj.save()
  File "/home/admin1/Desktop/Environments/Bynry-360/lib/python3.6/site-packages/django/db/models/base.py", line 746, in save
    force_update=force_update, update_fields=update_fields)
  File "/home/admin1/Desktop/Environments/Bynry-360/lib/python3.6/site-packages/django/db/models/base.py", line 784, in save_base
    force_update, using, update_fields,
  File "/home/admin1/Desktop/Environments/Bynry-360/lib/python3.6/site-packages/django/db/models/base.py", line 865, in _save_table
    forced_update)
  File "/home/admin1/Desktop/Environments/Bynry-360/lib/python3.6/site-packages/django/db/models/base.py", line 917, in _do_update
    return filtered._update(values) > 0
  File "/home/admin1/Desktop/Environments/Bynry-360/lib/python3.6/site-packages/django/db/models/query.py", line 771, in _update
    return query.get_compiler(self.db).execute_sql(CURSOR)
  File "/home/admin1/Desktop/Environments/Bynry-360/lib/python3.6/site-packages/django/db/models/sql/compiler.py", line 1492, in execute_sql
    cursor = super().execute_sql(result_type)
  File "/home/admin1/Desktop/Environments/Bynry-360/lib/python3.6/site-packages/django/db/models/sql/compiler.py", line 1131, in execute_sql
    sql, params = self.as_sql()
  File "/home/admin1/Desktop/Environments/Bynry-360/lib/python3.6/site-packages/django/db/models/sql/compiler.py", line 1455, in as_sql
    % (field, val, field.__class__.__name__)
TypeError: Tried to update field registration.Registration.updated_by with a model instance, <UserDetail: rohan>. Use a value compatible with BigIntegerField.

During handling of the above exception, another exception occurred:

Traceback (most recent call last):
  File "/home/admin1/Desktop/Environments/Bynry-360/lib/python3.6/site-packages/django/core/handlers/exception.py", line 34, in inner
    response = get_response(request)
  File "/home/admin1/Desktop/Environments/Bynry-360/lib/python3.6/site-packages/django/core/handlers/base.py", line 115, in _get_response
    response = self.process_exception_by_middleware(e, request)
  File "/home/admin1/Desktop/Environments/Bynry-360/lib/python3.6/site-packages/django/core/handlers/base.py", line 113, in _get_response
    response = wrapped_callback(request, *callback_args, **callback_kwargs)
  File "/home/admin1/Desktop/Environments/Bynry-360/lib/python3.6/site-packages/django/views/decorators/csrf.py", line 54, in wrapped_view
    return view_func(*args, **kwargs)
  File "/home/admin1/Desktop/Environments/Bynry-360/lib/python3.6/site-packages/django/views/generic/base.py", line 71, in view
    return self.dispatch(request, *args, **kwargs)
  File "/home/admin1/Desktop/Environments/Bynry-360/lib/python3.6/site-packages/rest_framework/views.py", line 505, in dispatch
    response = self.handle_exception(exc)
  File "/home/admin1/Desktop/Environments/Bynry-360/lib/python3.6/site-packages/rest_framework/views.py", line 465, in handle_exception
    self.raise_uncaught_exception(exc)
  File "/home/admin1/Desktop/Environments/Bynry-360/lib/python3.6/site-packages/rest_framework/views.py", line 476, in raise_uncaught_exception
    raise exc
  File "/home/admin1/Desktop/Environments/Bynry-360/lib/python3.6/site-packages/rest_framework/views.py", line 502, in dispatch
    response = handler(request, *args, **kwargs)
  File "/home/admin1/yy/Smart360-app/api/v1/registration/views/registrations.py", line 184, in put
    ERROR: str(traceback.print_exc(e))
  File "/usr/lib/python3.6/traceback.py", line 163, in print_exc
    print_exception(*sys.exc_info(), limit=limit, file=file, chain=chain)
  File "/usr/lib/python3.6/traceback.py", line 104, in print_exception
    type(value), value, tb, limit=limit).format(chain=chain):
  File "/usr/lib/python3.6/traceback.py", line 509, in __init__
    capture_locals=capture_locals)
  File "/usr/lib/python3.6/traceback.py", line 338, in extract
    if limit >= 0:
TypeError: '>=' not supported between instances of 'TypeError' and 'int'
"PUT /api/v1/registration/4d5e2355-80e1-4765-9a4f-f0fab5d24035 HTTP/1.1" 500 20132
/home/admin1/yy/Smart360-app/api/v1/registration/views/registrations.py changed, reloading.
Watching for file changes with StatReloader
Internal Server Error: /api/v1/registration/4d5e2355-80e1-4765-9a4f-f0fab5d24035
Traceback (most recent call last):
  File "/home/admin1/yy/Smart360-app/api/v1/registration/views/registrations.py", line 156, in put
    registration_obj = serializer.update(registration_obj,serializer.validated_data, user)
  File "/home/admin1/yy/Smart360-app/api/v1/registration/serializers/registration.py", line 102, in update
    registration_obj.save()
  File "/home/admin1/Desktop/Environments/Bynry-360/lib/python3.6/site-packages/django/db/models/base.py", line 746, in save
    force_update=force_update, update_fields=update_fields)
  File "/home/admin1/Desktop/Environments/Bynry-360/lib/python3.6/site-packages/django/db/models/base.py", line 784, in save_base
    force_update, using, update_fields,
  File "/home/admin1/Desktop/Environments/Bynry-360/lib/python3.6/site-packages/django/db/models/base.py", line 865, in _save_table
    forced_update)
  File "/home/admin1/Desktop/Environments/Bynry-360/lib/python3.6/site-packages/django/db/models/base.py", line 917, in _do_update
    return filtered._update(values) > 0
  File "/home/admin1/Desktop/Environments/Bynry-360/lib/python3.6/site-packages/django/db/models/query.py", line 771, in _update
    return query.get_compiler(self.db).execute_sql(CURSOR)
  File "/home/admin1/Desktop/Environments/Bynry-360/lib/python3.6/site-packages/django/db/models/sql/compiler.py", line 1492, in execute_sql
    cursor = super().execute_sql(result_type)
  File "/home/admin1/Desktop/Environments/Bynry-360/lib/python3.6/site-packages/django/db/models/sql/compiler.py", line 1131, in execute_sql
    sql, params = self.as_sql()
  File "/home/admin1/Desktop/Environments/Bynry-360/lib/python3.6/site-packages/django/db/models/sql/compiler.py", line 1455, in as_sql
    % (field, val, field.__class__.__name__)
TypeError: Tried to update field registration.Registration.updated_by with a model instance, <UserDetail: rohan>. Use a value compatible with BigIntegerField.

During handling of the above exception, another exception occurred:

Traceback (most recent call last):
  File "/home/admin1/Desktop/Environments/Bynry-360/lib/python3.6/site-packages/django/core/handlers/exception.py", line 34, in inner
    response = get_response(request)
  File "/home/admin1/Desktop/Environments/Bynry-360/lib/python3.6/site-packages/django/core/handlers/base.py", line 115, in _get_response
    response = self.process_exception_by_middleware(e, request)
  File "/home/admin1/Desktop/Environments/Bynry-360/lib/python3.6/site-packages/django/core/handlers/base.py", line 113, in _get_response
    response = wrapped_callback(request, *callback_args, **callback_kwargs)
  File "/home/admin1/Desktop/Environments/Bynry-360/lib/python3.6/site-packages/django/views/decorators/csrf.py", line 54, in wrapped_view
    return view_func(*args, **kwargs)
  File "/home/admin1/Desktop/Environments/Bynry-360/lib/python3.6/site-packages/django/views/generic/base.py", line 71, in view
    return self.dispatch(request, *args, **kwargs)
  File "/home/admin1/Desktop/Environments/Bynry-360/lib/python3.6/site-packages/rest_framework/views.py", line 505, in dispatch
    response = self.handle_exception(exc)
  File "/home/admin1/Desktop/Environments/Bynry-360/lib/python3.6/site-packages/rest_framework/views.py", line 465, in handle_exception
    self.raise_uncaught_exception(exc)
  File "/home/admin1/Desktop/Environments/Bynry-360/lib/python3.6/site-packages/rest_framework/views.py", line 476, in raise_uncaught_exception
    raise exc
  File "/home/admin1/Desktop/Environments/Bynry-360/lib/python3.6/site-packages/rest_framework/views.py", line 502, in dispatch
    response = handler(request, *args, **kwargs)
  File "/home/admin1/yy/Smart360-app/api/v1/registration/views/registrations.py", line 184, in put
    ERROR: str(traceback.print_exc(e))
  File "/usr/lib/python3.6/traceback.py", line 163, in print_exc
    print_exception(*sys.exc_info(), limit=limit, file=file, chain=chain)
  File "/usr/lib/python3.6/traceback.py", line 104, in print_exception
    type(value), value, tb, limit=limit).format(chain=chain):
  File "/usr/lib/python3.6/traceback.py", line 509, in __init__
    capture_locals=capture_locals)
  File "/usr/lib/python3.6/traceback.py", line 338, in extract
    if limit >= 0:
TypeError: '>=' not supported between instances of 'TypeError' and 'int'
"PUT /api/v1/registration/4d5e2355-80e1-4765-9a4f-f0fab5d24035 HTTP/1.1" 500 20132
/home/admin1/yy/Smart360-app/api/v1/registration/views/registrations.py changed, reloading.
Watching for file changes with StatReloader
Internal Server Error: /api/v1/registration/4d5e2355-80e1-4765-9a4f-f0fab5d24035
Traceback (most recent call last):
  File "/home/admin1/yy/Smart360-app/api/v1/registration/views/registrations.py", line 156, in put
    registration_obj = serializer.update(registration_obj,serializer.validated_data, user)
  File "/home/admin1/yy/Smart360-app/api/v1/registration/serializers/registration.py", line 102, in update
    registration_obj.save()
  File "/home/admin1/Desktop/Environments/Bynry-360/lib/python3.6/site-packages/django/db/models/base.py", line 746, in save
    force_update=force_update, update_fields=update_fields)
  File "/home/admin1/Desktop/Environments/Bynry-360/lib/python3.6/site-packages/django/db/models/base.py", line 784, in save_base
    force_update, using, update_fields,
  File "/home/admin1/Desktop/Environments/Bynry-360/lib/python3.6/site-packages/django/db/models/base.py", line 865, in _save_table
    forced_update)
  File "/home/admin1/Desktop/Environments/Bynry-360/lib/python3.6/site-packages/django/db/models/base.py", line 917, in _do_update
    return filtered._update(values) > 0
  File "/home/admin1/Desktop/Environments/Bynry-360/lib/python3.6/site-packages/django/db/models/query.py", line 771, in _update
    return query.get_compiler(self.db).execute_sql(CURSOR)
  File "/home/admin1/Desktop/Environments/Bynry-360/lib/python3.6/site-packages/django/db/models/sql/compiler.py", line 1492, in execute_sql
    cursor = super().execute_sql(result_type)
  File "/home/admin1/Desktop/Environments/Bynry-360/lib/python3.6/site-packages/django/db/models/sql/compiler.py", line 1131, in execute_sql
    sql, params = self.as_sql()
  File "/home/admin1/Desktop/Environments/Bynry-360/lib/python3.6/site-packages/django/db/models/sql/compiler.py", line 1455, in as_sql
    % (field, val, field.__class__.__name__)
TypeError: Tried to update field registration.Registration.updated_by with a model instance, <UserDetail: rohan>. Use a value compatible with BigIntegerField.

During handling of the above exception, another exception occurred:

Traceback (most recent call last):
  File "/home/admin1/Desktop/Environments/Bynry-360/lib/python3.6/site-packages/django/core/handlers/exception.py", line 34, in inner
    response = get_response(request)
  File "/home/admin1/Desktop/Environments/Bynry-360/lib/python3.6/site-packages/django/core/handlers/base.py", line 115, in _get_response
    response = self.process_exception_by_middleware(e, request)
  File "/home/admin1/Desktop/Environments/Bynry-360/lib/python3.6/site-packages/django/core/handlers/base.py", line 113, in _get_response
    response = wrapped_callback(request, *callback_args, **callback_kwargs)
  File "/home/admin1/Desktop/Environments/Bynry-360/lib/python3.6/site-packages/django/views/decorators/csrf.py", line 54, in wrapped_view
    return view_func(*args, **kwargs)
  File "/home/admin1/Desktop/Environments/Bynry-360/lib/python3.6/site-packages/django/views/generic/base.py", line 71, in view
    return self.dispatch(request, *args, **kwargs)
  File "/home/admin1/Desktop/Environments/Bynry-360/lib/python3.6/site-packages/rest_framework/views.py", line 505, in dispatch
    response = self.handle_exception(exc)
  File "/home/admin1/Desktop/Environments/Bynry-360/lib/python3.6/site-packages/rest_framework/views.py", line 465, in handle_exception
    self.raise_uncaught_exception(exc)
  File "/home/admin1/Desktop/Environments/Bynry-360/lib/python3.6/site-packages/rest_framework/views.py", line 476, in raise_uncaught_exception
    raise exc
  File "/home/admin1/Desktop/Environments/Bynry-360/lib/python3.6/site-packages/rest_framework/views.py", line 502, in dispatch
    response = handler(request, *args, **kwargs)
  File "/home/admin1/yy/Smart360-app/api/v1/registration/views/registrations.py", line 181, in put
    print("@@@@@@@@@@@@@",str(traceback.print_exc(e)))
  File "/usr/lib/python3.6/traceback.py", line 163, in print_exc
    print_exception(*sys.exc_info(), limit=limit, file=file, chain=chain)
  File "/usr/lib/python3.6/traceback.py", line 104, in print_exception
    type(value), value, tb, limit=limit).format(chain=chain):
  File "/usr/lib/python3.6/traceback.py", line 509, in __init__
    capture_locals=capture_locals)
  File "/usr/lib/python3.6/traceback.py", line 338, in extract
    if limit >= 0:
TypeError: '>=' not supported between instances of 'TypeError' and 'int'
"PUT /api/v1/registration/4d5e2355-80e1-4765-9a4f-f0fab5d24035 HTTP/1.1" 500 20148
/home/admin1/yy/Smart360-app/api/v1/registration/views/registrations.py changed, reloading.
Watching for file changes with StatReloader
Internal Server Error: /api/v1/registration/4d5e2355-80e1-4765-9a4f-f0fab5d24035
"PUT /api/v1/registration/4d5e2355-80e1-4765-9a4f-f0fab5d24035 HTTP/1.1" 500 37
/home/admin1/yy/Smart360-app/api/v1/registration/views/registrations.py changed, reloading.
Watching for file changes with StatReloader
Internal Server Error: /api/v1/registration/4d5e2355-80e1-4765-9a4f-f0fab5d24035
"PUT /api/v1/registration/4d5e2355-80e1-4765-9a4f-f0fab5d24035 HTTP/1.1" 500 37
/home/admin1/yy/Smart360-app/api/v1/registration/views/registrations.py changed, reloading.
Watching for file changes with StatReloader
Internal Server Error: /api/v1/registration/4d5e2355-80e1-4765-9a4f-f0fab5d24035
Traceback (most recent call last):
  File "/home/admin1/yy/Smart360-app/api/v1/registration/views/registrations.py", line 156, in put
    registration_obj = serializer.update(registration_obj,serializer.validated_data, user)
  File "/home/admin1/yy/Smart360-app/api/v1/registration/serializers/registration.py", line 102, in update
    registration_obj.save()
  File "/home/admin1/Desktop/Environments/Bynry-360/lib/python3.6/site-packages/django/db/models/base.py", line 746, in save
    force_update=force_update, update_fields=update_fields)
  File "/home/admin1/Desktop/Environments/Bynry-360/lib/python3.6/site-packages/django/db/models/base.py", line 784, in save_base
    force_update, using, update_fields,
  File "/home/admin1/Desktop/Environments/Bynry-360/lib/python3.6/site-packages/django/db/models/base.py", line 865, in _save_table
    forced_update)
  File "/home/admin1/Desktop/Environments/Bynry-360/lib/python3.6/site-packages/django/db/models/base.py", line 917, in _do_update
    return filtered._update(values) > 0
  File "/home/admin1/Desktop/Environments/Bynry-360/lib/python3.6/site-packages/django/db/models/query.py", line 771, in _update
    return query.get_compiler(self.db).execute_sql(CURSOR)
  File "/home/admin1/Desktop/Environments/Bynry-360/lib/python3.6/site-packages/django/db/models/sql/compiler.py", line 1492, in execute_sql
    cursor = super().execute_sql(result_type)
  File "/home/admin1/Desktop/Environments/Bynry-360/lib/python3.6/site-packages/django/db/models/sql/compiler.py", line 1131, in execute_sql
    sql, params = self.as_sql()
  File "/home/admin1/Desktop/Environments/Bynry-360/lib/python3.6/site-packages/django/db/models/sql/compiler.py", line 1455, in as_sql
    % (field, val, field.__class__.__name__)
TypeError: Tried to update field registration.Registration.updated_by with a model instance, <UserDetail: rohan>. Use a value compatible with BigIntegerField.

During handling of the above exception, another exception occurred:

Traceback (most recent call last):
  File "/home/admin1/Desktop/Environments/Bynry-360/lib/python3.6/site-packages/django/core/handlers/exception.py", line 34, in inner
    response = get_response(request)
  File "/home/admin1/Desktop/Environments/Bynry-360/lib/python3.6/site-packages/django/core/handlers/base.py", line 115, in _get_response
    response = self.process_exception_by_middleware(e, request)
  File "/home/admin1/Desktop/Environments/Bynry-360/lib/python3.6/site-packages/django/core/handlers/base.py", line 113, in _get_response
    response = wrapped_callback(request, *callback_args, **callback_kwargs)
  File "/home/admin1/Desktop/Environments/Bynry-360/lib/python3.6/site-packages/django/views/decorators/csrf.py", line 54, in wrapped_view
    return view_func(*args, **kwargs)
  File "/home/admin1/Desktop/Environments/Bynry-360/lib/python3.6/site-packages/django/views/generic/base.py", line 71, in view
    return self.dispatch(request, *args, **kwargs)
  File "/home/admin1/Desktop/Environments/Bynry-360/lib/python3.6/site-packages/rest_framework/views.py", line 505, in dispatch
    response = self.handle_exception(exc)
  File "/home/admin1/Desktop/Environments/Bynry-360/lib/python3.6/site-packages/rest_framework/views.py", line 465, in handle_exception
    self.raise_uncaught_exception(exc)
  File "/home/admin1/Desktop/Environments/Bynry-360/lib/python3.6/site-packages/rest_framework/views.py", line 476, in raise_uncaught_exception
    raise exc
  File "/home/admin1/Desktop/Environments/Bynry-360/lib/python3.6/site-packages/rest_framework/views.py", line 502, in dispatch
    response = handler(request, *args, **kwargs)
  File "/home/admin1/yy/Smart360-app/api/v1/registration/views/registrations.py", line 181, in put
    print("@@@@@@@@@@@@@",traceback.print_exc(e))
  File "/usr/lib/python3.6/traceback.py", line 163, in print_exc
    print_exception(*sys.exc_info(), limit=limit, file=file, chain=chain)
  File "/usr/lib/python3.6/traceback.py", line 104, in print_exception
    type(value), value, tb, limit=limit).format(chain=chain):
  File "/usr/lib/python3.6/traceback.py", line 509, in __init__
    capture_locals=capture_locals)
  File "/usr/lib/python3.6/traceback.py", line 338, in extract
    if limit >= 0:
TypeError: '>=' not supported between instances of 'TypeError' and 'int'
"PUT /api/v1/registration/4d5e2355-80e1-4765-9a4f-f0fab5d24035 HTTP/1.1" 500 20143
/home/admin1/yy/Smart360-app/api/v1/registration/views/registrations.py changed, reloading.
Watching for file changes with StatReloader
Internal Server Error: /api/v1/registration/4d5e2355-80e1-4765-9a4f-f0fab5d24035
"PUT /api/v1/registration/4d5e2355-80e1-4765-9a4f-f0fab5d24035 HTTP/1.1" 500 37
/home/admin1/yy/Smart360-app/api/v1/registration/serializers/registration.py changed, reloading.
Watching for file changes with StatReloader
"PUT /api/v1/registration/4d5e2355-80e1-4765-9a4f-f0fab5d24035 HTTP/1.1" 200 574
"GET /api/v1/registration/4d5e2355-80e1-4765-9a4f-f0fab5d24035 HTTP/1.1" 200 571
"PUT /api/v1/registration/4d5e2355-80e1-4765-9a4f-f0fab5d24035 HTTP/1.1" 200 574
"GET /admin/registration/registration/ HTTP/1.1" 200 5113
"GET /admin/jsi18n/ HTTP/1.1" 200 3223
"POST /admin/registration/registration/ HTTP/1.1" 200 3405
"POST /admin/registration/registration/ HTTP/1.1" 302 0
"GET /admin/registration/registration/ HTTP/1.1" 200 5009
"GET /admin/jsi18n/ HTTP/1.1" 200 3223
/home/admin1/yy/Smart360-app/api/v1/registration/views/registrations.py changed, reloading.
Watching for file changes with StatReloader
/home/admin1/yy/Smart360-app/api/v1/registration/serializers/registration.py changed, reloading.
Watching for file changes with StatReloader
/home/admin1/yy/Smart360-app/api/v1/registration/serializers/registration.py changed, reloading.
Watching for file changes with StatReloader
Not Found: /api/v1/registration/
"POST /api/v1/registration/ HTTP/1.1" 404 4561
Not Found: /api/v1/registration/
"POST /api/v1/registration/ HTTP/1.1" 404 4561
Not Found: /api/v1/registration/
"POST /api/v1/registration/ HTTP/1.1" 404 4561
Not Found: /api/v1/registration/
"POST /api/v1/registration/ HTTP/1.1" 404 4561
Not Found: /api/v1/registration/
"POST /api/v1/registration/ HTTP/1.1" 404 4561
Not Found: /api/v1/registration/
"POST /api/v1/registration/ HTTP/1.1" 404 4561
Not Found: /api/v1/registration/
"POST /api/v1/registration/ HTTP/1.1" 404 4561
"GET /api/v1/registration/list HTTP/1.1" 200 988
"GET /api/v1/registration/4d5e2355-80e1-4765-9a4f-f0fab5d24035 HTTP/1.1" 200 571
"GET /admin/registration/registration/ HTTP/1.1" 200 4881
"GET /admin/jsi18n/ HTTP/1.1" 200 3223
"GET /admin/registration/registration/ HTTP/1.1" 200 4881
"GET /admin/jsi18n/ HTTP/1.1" 200 3223
Not Found: /api/v1/registration/
"POST /api/v1/registration/ HTTP/1.1" 404 4561
Not Found: /api/v1/registration/
"POST /api/v1/registration/ HTTP/1.1" 404 4561
Not Found: /api/v1/registration/
"POST /api/v1/registration/ HTTP/1.1" 404 4561
Not Found: /api/v1/registration/
"POST /api/v1/registration/ HTTP/1.1" 404 4561
"PUT /api/v1/registration/4d5e2355-80e1-4765-9a4f-f0fab5d24035 HTTP/1.1" 200 574
Not Found: /api/v1/registration/
"POST /api/v1/registration/ HTTP/1.1" 404 4561
Not Found: /api/v1/registration/
"POST /api/v1/registration/ HTTP/1.1" 404 4561
/home/admin1/yy/Smart360-app/api/v1/registration/urls.py changed, reloading.
Watching for file changes with StatReloader
Internal Server Error: /api/v1/registration/
Traceback (most recent call last):
  File "/home/admin1/yy/Smart360-app/api/v1/registration/views/registrations.py", line 101, in post
    registration_obj = serializer.create(serializer.validated_data, user)
  File "/home/admin1/yy/Smart360-app/api/v1/registration/serializers/registration.py", line 74, in create
    validated_data =  set_validated_data(validated_data)
  File "/home/admin1/yy/Smart360-app/api/v1/registration/views/common_functions.py", line 23, in set_validated_data
    validated_data["area_id"] = area.id
AttributeError: 'NoneType' object has no attribute 'id'

During handling of the above exception, another exception occurred:

Traceback (most recent call last):
  File "/home/admin1/Desktop/Environments/Bynry-360/lib/python3.6/site-packages/django/core/handlers/exception.py", line 34, in inner
    response = get_response(request)
  File "/home/admin1/Desktop/Environments/Bynry-360/lib/python3.6/site-packages/django/core/handlers/base.py", line 115, in _get_response
    response = self.process_exception_by_middleware(e, request)
  File "/home/admin1/Desktop/Environments/Bynry-360/lib/python3.6/site-packages/django/core/handlers/base.py", line 113, in _get_response
    response = wrapped_callback(request, *callback_args, **callback_kwargs)
  File "/home/admin1/Desktop/Environments/Bynry-360/lib/python3.6/site-packages/django/views/decorators/csrf.py", line 54, in wrapped_view
    return view_func(*args, **kwargs)
  File "/home/admin1/Desktop/Environments/Bynry-360/lib/python3.6/site-packages/django/views/generic/base.py", line 71, in view
    return self.dispatch(request, *args, **kwargs)
  File "/home/admin1/Desktop/Environments/Bynry-360/lib/python3.6/site-packages/rest_framework/views.py", line 505, in dispatch
    response = self.handle_exception(exc)
  File "/home/admin1/Desktop/Environments/Bynry-360/lib/python3.6/site-packages/rest_framework/views.py", line 465, in handle_exception
    self.raise_uncaught_exception(exc)
  File "/home/admin1/Desktop/Environments/Bynry-360/lib/python3.6/site-packages/rest_framework/views.py", line 476, in raise_uncaught_exception
    raise exc
  File "/home/admin1/Desktop/Environments/Bynry-360/lib/python3.6/site-packages/rest_framework/views.py", line 502, in dispatch
    response = handler(request, *args, **kwargs)
  File "/home/admin1/yy/Smart360-app/api/v1/registration/views/registrations.py", line 125, in post
    traceback.print_exc(e)
  File "/usr/lib/python3.6/traceback.py", line 163, in print_exc
    print_exception(*sys.exc_info(), limit=limit, file=file, chain=chain)
  File "/usr/lib/python3.6/traceback.py", line 104, in print_exception
    type(value), value, tb, limit=limit).format(chain=chain):
  File "/usr/lib/python3.6/traceback.py", line 509, in __init__
    capture_locals=capture_locals)
  File "/usr/lib/python3.6/traceback.py", line 338, in extract
    if limit >= 0:
TypeError: '>=' not supported between instances of 'AttributeError' and 'int'
"POST /api/v1/registration/ HTTP/1.1" 500 18644
Internal Server Error: /api/v1/registration/
Traceback (most recent call last):
  File "/home/admin1/yy/Smart360-app/api/v1/registration/views/registrations.py", line 101, in post
    registration_obj = serializer.create(serializer.validated_data, user)
  File "/home/admin1/yy/Smart360-app/api/v1/registration/serializers/registration.py", line 74, in create
    validated_data =  set_validated_data(validated_data)
  File "/home/admin1/yy/Smart360-app/api/v1/registration/views/common_functions.py", line 23, in set_validated_data
    validated_data["area_id"] = area.id
AttributeError: 'NoneType' object has no attribute 'id'

During handling of the above exception, another exception occurred:

Traceback (most recent call last):
  File "/home/admin1/Desktop/Environments/Bynry-360/lib/python3.6/site-packages/django/core/handlers/exception.py", line 34, in inner
    response = get_response(request)
  File "/home/admin1/Desktop/Environments/Bynry-360/lib/python3.6/site-packages/django/core/handlers/base.py", line 115, in _get_response
    response = self.process_exception_by_middleware(e, request)
  File "/home/admin1/Desktop/Environments/Bynry-360/lib/python3.6/site-packages/django/core/handlers/base.py", line 113, in _get_response
    response = wrapped_callback(request, *callback_args, **callback_kwargs)
  File "/home/admin1/Desktop/Environments/Bynry-360/lib/python3.6/site-packages/django/views/decorators/csrf.py", line 54, in wrapped_view
    return view_func(*args, **kwargs)
  File "/home/admin1/Desktop/Environments/Bynry-360/lib/python3.6/site-packages/django/views/generic/base.py", line 71, in view
    return self.dispatch(request, *args, **kwargs)
  File "/home/admin1/Desktop/Environments/Bynry-360/lib/python3.6/site-packages/rest_framework/views.py", line 505, in dispatch
    response = self.handle_exception(exc)
  File "/home/admin1/Desktop/Environments/Bynry-360/lib/python3.6/site-packages/rest_framework/views.py", line 465, in handle_exception
    self.raise_uncaught_exception(exc)
  File "/home/admin1/Desktop/Environments/Bynry-360/lib/python3.6/site-packages/rest_framework/views.py", line 476, in raise_uncaught_exception
    raise exc
  File "/home/admin1/Desktop/Environments/Bynry-360/lib/python3.6/site-packages/rest_framework/views.py", line 502, in dispatch
    response = handler(request, *args, **kwargs)
  File "/home/admin1/yy/Smart360-app/api/v1/registration/views/registrations.py", line 125, in post
    traceback.print_exc(e)
  File "/usr/lib/python3.6/traceback.py", line 163, in print_exc
    print_exception(*sys.exc_info(), limit=limit, file=file, chain=chain)
  File "/usr/lib/python3.6/traceback.py", line 104, in print_exception
    type(value), value, tb, limit=limit).format(chain=chain):
  File "/usr/lib/python3.6/traceback.py", line 509, in __init__
    capture_locals=capture_locals)
  File "/usr/lib/python3.6/traceback.py", line 338, in extract
    if limit >= 0:
TypeError: '>=' not supported between instances of 'AttributeError' and 'int'
"POST /api/v1/registration/ HTTP/1.1" 500 18644
Watching for file changes with StatReloader
Internal Server Error: /api/v1/registration/
Traceback (most recent call last):
  File "/home/admin1/yy/Smart360-app/api/v1/registration/views/registrations.py", line 101, in post
    registration_obj = serializer.create(serializer.validated_data, user)
  File "/home/admin1/yy/Smart360-app/api/v1/registration/serializers/registration.py", line 74, in create
    validated_data =  set_validated_data(validated_data)
  File "/home/admin1/yy/Smart360-app/api/v1/registration/views/common_functions.py", line 23, in set_validated_data
    validated_data["area_id"] = area.id
AttributeError: 'NoneType' object has no attribute 'id'

During handling of the above exception, another exception occurred:

Traceback (most recent call last):
  File "/home/admin1/Desktop/Environments/Bynry-360/lib/python3.6/site-packages/django/core/handlers/exception.py", line 34, in inner
    response = get_response(request)
  File "/home/admin1/Desktop/Environments/Bynry-360/lib/python3.6/site-packages/django/core/handlers/base.py", line 115, in _get_response
    response = self.process_exception_by_middleware(e, request)
  File "/home/admin1/Desktop/Environments/Bynry-360/lib/python3.6/site-packages/django/core/handlers/base.py", line 113, in _get_response
    response = wrapped_callback(request, *callback_args, **callback_kwargs)
  File "/home/admin1/Desktop/Environments/Bynry-360/lib/python3.6/site-packages/django/views/decorators/csrf.py", line 54, in wrapped_view
    return view_func(*args, **kwargs)
  File "/home/admin1/Desktop/Environments/Bynry-360/lib/python3.6/site-packages/django/views/generic/base.py", line 71, in view
    return self.dispatch(request, *args, **kwargs)
  File "/home/admin1/Desktop/Environments/Bynry-360/lib/python3.6/site-packages/rest_framework/views.py", line 505, in dispatch
    response = self.handle_exception(exc)
  File "/home/admin1/Desktop/Environments/Bynry-360/lib/python3.6/site-packages/rest_framework/views.py", line 465, in handle_exception
    self.raise_uncaught_exception(exc)
  File "/home/admin1/Desktop/Environments/Bynry-360/lib/python3.6/site-packages/rest_framework/views.py", line 476, in raise_uncaught_exception
    raise exc
  File "/home/admin1/Desktop/Environments/Bynry-360/lib/python3.6/site-packages/rest_framework/views.py", line 502, in dispatch
    response = handler(request, *args, **kwargs)
  File "/home/admin1/yy/Smart360-app/api/v1/registration/views/registrations.py", line 125, in post
    traceback.print_exc(e)
  File "/usr/lib/python3.6/traceback.py", line 163, in print_exc
    print_exception(*sys.exc_info(), limit=limit, file=file, chain=chain)
  File "/usr/lib/python3.6/traceback.py", line 104, in print_exception
    type(value), value, tb, limit=limit).format(chain=chain):
  File "/usr/lib/python3.6/traceback.py", line 509, in __init__
    capture_locals=capture_locals)
  File "/usr/lib/python3.6/traceback.py", line 338, in extract
    if limit >= 0:
TypeError: '>=' not supported between instances of 'AttributeError' and 'int'
"POST /api/v1/registration/ HTTP/1.1" 500 18644
"GET /api/v1/registration/list HTTP/1.1" 200 988
"GET /api/v1/registration/4d5e2355-80e1-4765-9a4f-f0fab5d24035 HTTP/1.1" 200 571
"POST /api/v1/registration/ HTTP/1.1" 201 550
"GET /admin/registration/registration/ HTTP/1.1" 200 5113
"GET /admin/jsi18n/ HTTP/1.1" 200 3223
"PUT /api/v1/registration/65b3c679-7559-45d2-886d-399ce479c051 HTTP/1.1" 200 549
Watching for file changes with StatReloader
"GET /api/v1/registration/list HTTP/1.1" 200 988
"GET /api/v1/registration/4d5e2355-80e1-4765-9a4f-f0fab5d24035 HTTP/1.1" 200 571
"POST /api/v1/registration/ HTTP/1.1" 201 550
"GET /api/v1/registration/list HTTP/1.1" 200 988
"GET /admin/ HTTP/1.1" 200 41131
"GET /static/admin/css/base.css HTTP/1.1" 200 16378
"GET /static/admin/css/responsive.css HTTP/1.1" 200 18052
"GET /static/admin/fonts/Roboto-Light-webfont.woff HTTP/1.1" 200 85692
"GET /static/admin/fonts/Roboto-Bold-webfont.woff HTTP/1.1" 200 86184
"GET /static/admin/fonts/Roboto-Regular-webfont.woff HTTP/1.1" 200 85876
Not Found: /favicon.ico
"GET /favicon.ico HTTP/1.1" 404 2657
"GET /admin/registration/registration/ HTTP/1.1" 200 5344
"GET /static/admin/css/changelists.css HTTP/1.1" 200 6190
"GET /static/admin/js/core.js HTTP/1.1" 200 5723
"GET /static/admin/js/actions.js HTTP/1.1" 200 6766
"GET /static/admin/js/urlify.js HTTP/1.1" 200 8941
"GET /admin/jsi18n/ HTTP/1.1" 200 3223
"GET /static/admin/js/vendor/jquery/jquery.js HTTP/1.1" 200 280364
"GET /static/admin/js/vendor/xregexp/xregexp.js HTTP/1.1" 200 128820
"POST /admin/registration/registration/ HTTP/1.1" 200 3559
"POST /admin/registration/registration/ HTTP/1.1" 302 0
"GET /admin/registration/registration/ HTTP/1.1" 200 5010
"GET /admin/jsi18n/ HTTP/1.1" 200 3223
"POST /api/v1/registration/ HTTP/1.1" 201 550
"GET /api/v1/registration/list HTTP/1.1" 200 1277
"GET /admin/registration/registration/ HTTP/1.1" 200 5113
"GET /admin/jsi18n/ HTTP/1.1" 200 3223
"POST /admin/registration/registration/ HTTP/1.1" 200 3405
"POST /admin/registration/registration/ HTTP/1.1" 302 0
"GET /admin/registration/registration/ HTTP/1.1" 200 5009
"GET /admin/jsi18n/ HTTP/1.1" 200 3223
Internal Server Error: /api/v1/registration/
Traceback (most recent call last):
  File "/home/admin1/Desktop/Environments/Bynry-360/lib/python3.6/site-packages/rest_framework/parsers.py", line 65, in parse
    return json.load(decoded_stream, parse_constant=parse_constant)
  File "/home/admin1/Desktop/Environments/Bynry-360/lib/python3.6/site-packages/rest_framework/utils/json.py", line 31, in load
    return json.load(*args, **kwargs)
  File "/usr/lib/python3.6/json/__init__.py", line 299, in load
    parse_constant=parse_constant, object_pairs_hook=object_pairs_hook, **kw)
  File "/usr/lib/python3.6/json/__init__.py", line 367, in loads
    return cls(**kw).decode(s)
  File "/usr/lib/python3.6/json/decoder.py", line 339, in decode
    obj, end = self.raw_decode(s, idx=_w(s, 0).end())
  File "/usr/lib/python3.6/json/decoder.py", line 355, in raw_decode
    obj, end = self.scan_once(s, idx)
json.decoder.JSONDecodeError: Expecting ',' delimiter: line 5 column 2 (char 81)

During handling of the above exception, another exception occurred:

Traceback (most recent call last):
  File "/home/admin1/yy/Smart360-app/api/v1/registration/views/registrations.py", line 84, in post
    if is_token_valid(request.data['token']):
  File "/home/admin1/Desktop/Environments/Bynry-360/lib/python3.6/site-packages/rest_framework/request.py", line 209, in data
    self._load_data_and_files()
  File "/home/admin1/Desktop/Environments/Bynry-360/lib/python3.6/site-packages/rest_framework/request.py", line 272, in _load_data_and_files
    self._data, self._files = self._parse()
  File "/home/admin1/Desktop/Environments/Bynry-360/lib/python3.6/site-packages/rest_framework/request.py", line 347, in _parse
    parsed = parser.parse(stream, media_type, self.parser_context)
  File "/home/admin1/Desktop/Environments/Bynry-360/lib/python3.6/site-packages/rest_framework/parsers.py", line 67, in parse
    raise ParseError('JSON parse error - %s' % str(exc))
rest_framework.exceptions.ParseError: JSON parse error - Expecting ',' delimiter: line 5 column 2 (char 81)

During handling of the above exception, another exception occurred:

Traceback (most recent call last):
  File "/home/admin1/Desktop/Environments/Bynry-360/lib/python3.6/site-packages/django/core/handlers/exception.py", line 34, in inner
    response = get_response(request)
  File "/home/admin1/Desktop/Environments/Bynry-360/lib/python3.6/site-packages/django/core/handlers/base.py", line 115, in _get_response
    response = self.process_exception_by_middleware(e, request)
  File "/home/admin1/Desktop/Environments/Bynry-360/lib/python3.6/site-packages/django/core/handlers/base.py", line 113, in _get_response
    response = wrapped_callback(request, *callback_args, **callback_kwargs)
  File "/home/admin1/Desktop/Environments/Bynry-360/lib/python3.6/site-packages/django/views/decorators/csrf.py", line 54, in wrapped_view
    return view_func(*args, **kwargs)
  File "/home/admin1/Desktop/Environments/Bynry-360/lib/python3.6/site-packages/django/views/generic/base.py", line 71, in view
    return self.dispatch(request, *args, **kwargs)
  File "/home/admin1/Desktop/Environments/Bynry-360/lib/python3.6/site-packages/rest_framework/views.py", line 505, in dispatch
    response = self.handle_exception(exc)
  File "/home/admin1/Desktop/Environments/Bynry-360/lib/python3.6/site-packages/rest_framework/views.py", line 465, in handle_exception
    self.raise_uncaught_exception(exc)
  File "/home/admin1/Desktop/Environments/Bynry-360/lib/python3.6/site-packages/rest_framework/views.py", line 476, in raise_uncaught_exception
    raise exc
  File "/home/admin1/Desktop/Environments/Bynry-360/lib/python3.6/site-packages/rest_framework/views.py", line 502, in dispatch
    response = handler(request, *args, **kwargs)
  File "/home/admin1/yy/Smart360-app/api/v1/registration/views/registrations.py", line 121, in post
    traceback.print_exc(e)
  File "/usr/lib/python3.6/traceback.py", line 163, in print_exc
    print_exception(*sys.exc_info(), limit=limit, file=file, chain=chain)
  File "/usr/lib/python3.6/traceback.py", line 104, in print_exception
    type(value), value, tb, limit=limit).format(chain=chain):
  File "/usr/lib/python3.6/traceback.py", line 498, in __init__
    _seen=_seen)
  File "/usr/lib/python3.6/traceback.py", line 509, in __init__
    capture_locals=capture_locals)
  File "/usr/lib/python3.6/traceback.py", line 338, in extract
    if limit >= 0:
TypeError: '>=' not supported between instances of 'ParseError' and 'int'
"POST /api/v1/registration/ HTTP/1.1" 500 20059
"POST /api/v1/registration/ HTTP/1.1" 201 555
"GET /api/v1/registration/list HTTP/1.1" 200 1282
"GET /api/v1/registration/9d3f355b-0e0a-4d87-9a4e-c04129b333fe HTTP/1.1" 200 552
"GET /admin/registration/registration/ HTTP/1.1" 200 5115
"GET /admin/jsi18n/ HTTP/1.1" 200 3223
"GET /api/v1/registration/list HTTP/1.1" 200 1282
"GET /api/v1/registration/list?first_name=Desmond HTTP/1.1" 200 345
"GET /api/v1/registration/list HTTP/1.1" 200 1282
/home/admin1/yy/Smart360-app/api/v1/registration/serializers/registration.py changed, reloading.
Watching for file changes with StatReloader
"GET /api/v1/registration/list HTTP/1.1" 200 1282
"GET /api/v1/registration/list HTTP/1.1" 200 1282
Internal Server Error: /api/v1/registration/9d3f355b-0e0a-4d87-9a4e-c04129b333fe
"GET /api/v1/registration/9d3f355b-0e0a-4d87-9a4e-c04129b333fe HTTP/1.1" 500 31
/home/admin1/yy/Smart360-app/api/v1/registration/serializers/registration.py changed, reloading.
Watching for file changes with StatReloader
Internal Server Error: /api/v1/registration/list
Traceback (most recent call last):
  File "/home/admin1/Desktop/Environments/Bynry-360/lib/python3.6/site-packages/django/core/handlers/exception.py", line 34, in inner
    response = get_response(request)
  File "/home/admin1/Desktop/Environments/Bynry-360/lib/python3.6/site-packages/django/core/handlers/base.py", line 115, in _get_response
    response = self.process_exception_by_middleware(e, request)
  File "/home/admin1/Desktop/Environments/Bynry-360/lib/python3.6/site-packages/django/core/handlers/base.py", line 113, in _get_response
    response = wrapped_callback(request, *callback_args, **callback_kwargs)
  File "/home/admin1/Desktop/Environments/Bynry-360/lib/python3.6/site-packages/django/views/decorators/csrf.py", line 54, in wrapped_view
    return view_func(*args, **kwargs)
  File "/home/admin1/Desktop/Environments/Bynry-360/lib/python3.6/site-packages/django/views/generic/base.py", line 71, in view
    return self.dispatch(request, *args, **kwargs)
  File "/home/admin1/Desktop/Environments/Bynry-360/lib/python3.6/site-packages/rest_framework/views.py", line 505, in dispatch
    response = self.handle_exception(exc)
  File "/home/admin1/Desktop/Environments/Bynry-360/lib/python3.6/site-packages/rest_framework/views.py", line 465, in handle_exception
    self.raise_uncaught_exception(exc)
  File "/home/admin1/Desktop/Environments/Bynry-360/lib/python3.6/site-packages/rest_framework/views.py", line 476, in raise_uncaught_exception
    raise exc
  File "/home/admin1/Desktop/Environments/Bynry-360/lib/python3.6/site-packages/rest_framework/views.py", line 502, in dispatch
    response = handler(request, *args, **kwargs)
  File "/home/admin1/Desktop/Environments/Bynry-360/lib/python3.6/site-packages/rest_framework/generics.py", line 199, in get
    return self.list(request, *args, **kwargs)
  File "/home/admin1/Desktop/Environments/Bynry-360/lib/python3.6/site-packages/rest_framework/mixins.py", line 43, in list
    return self.get_paginated_response(serializer.data)
  File "/home/admin1/Desktop/Environments/Bynry-360/lib/python3.6/site-packages/rest_framework/serializers.py", line 760, in data
    ret = super().data
  File "/home/admin1/Desktop/Environments/Bynry-360/lib/python3.6/site-packages/rest_framework/serializers.py", line 260, in data
    self._data = self.to_representation(self.instance)
  File "/home/admin1/Desktop/Environments/Bynry-360/lib/python3.6/site-packages/rest_framework/serializers.py", line 678, in to_representation
    self.child.to_representation(item) for item in iterable
  File "/home/admin1/Desktop/Environments/Bynry-360/lib/python3.6/site-packages/rest_framework/serializers.py", line 678, in <listcomp>
    self.child.to_representation(item) for item in iterable
  File "/home/admin1/Desktop/Environments/Bynry-360/lib/python3.6/site-packages/rest_framework/serializers.py", line 529, in to_representation
    ret[field.field_name] = field.to_representation(attribute)
  File "/home/admin1/Desktop/Environments/Bynry-360/lib/python3.6/site-packages/rest_framework/fields.py", line 1255, in to_representation
    value = self.enforce_timezone(value)
  File "/home/admin1/Desktop/Environments/Bynry-360/lib/python3.6/site-packages/rest_framework/fields.py", line 1203, in enforce_timezone
    if timezone.is_aware(value):
  File "/home/admin1/Desktop/Environments/Bynry-360/lib/python3.6/site-packages/django/utils/timezone.py", line 248, in is_aware
    return value.utcoffset() is not None
AttributeError: 'datetime.date' object has no attribute 'utcoffset'
"GET /api/v1/registration/list HTTP/1.1" 500 19254
/home/admin1/yy/Smart360-app/api/v1/registration/models/registrations.py changed, reloading.
Watching for file changes with StatReloader
/home/admin1/yy/Smart360-app/api/v1/registration/models/registrations.py changed, reloading.
Watching for file changes with StatReloader
"POST /admin/registration/registration/ HTTP/1.1" 200 3865
"POST /admin/registration/registration/ HTTP/1.1" 302 0
"GET /admin/registration/registration/ HTTP/1.1" 200 3364
"GET /admin/jsi18n/ HTTP/1.1" 200 3223
"GET /api/v1/registration/list HTTP/1.1" 200 1048
"GET /admin/registration/registration/ HTTP/1.1" 200 4881
"GET /admin/jsi18n/ HTTP/1.1" 200 3223
Internal Server Error: /admin/registration/registration/3/change/
Traceback (most recent call last):
  File "/home/admin1/Desktop/Environments/Bynry-360/lib/python3.6/site-packages/django/core/handlers/exception.py", line 34, in inner
    response = get_response(request)
  File "/home/admin1/Desktop/Environments/Bynry-360/lib/python3.6/site-packages/django/core/handlers/base.py", line 145, in _get_response
    response = self.process_exception_by_middleware(e, request)
  File "/home/admin1/Desktop/Environments/Bynry-360/lib/python3.6/site-packages/django/core/handlers/base.py", line 143, in _get_response
    response = response.render()
  File "/home/admin1/Desktop/Environments/Bynry-360/lib/python3.6/site-packages/django/template/response.py", line 105, in render
    self.content = self.rendered_content
  File "/home/admin1/Desktop/Environments/Bynry-360/lib/python3.6/site-packages/django/template/response.py", line 83, in rendered_content
    return template.render(context, self._request)
  File "/home/admin1/Desktop/Environments/Bynry-360/lib/python3.6/site-packages/django/template/backends/django.py", line 61, in render
    return self.template.render(context)
  File "/home/admin1/Desktop/Environments/Bynry-360/lib/python3.6/site-packages/django/template/base.py", line 171, in render
    return self._render(context)
  File "/home/admin1/Desktop/Environments/Bynry-360/lib/python3.6/site-packages/django/template/base.py", line 163, in _render
    return self.nodelist.render(context)
  File "/home/admin1/Desktop/Environments/Bynry-360/lib/python3.6/site-packages/django/template/base.py", line 936, in render
    bit = node.render_annotated(context)
  File "/home/admin1/Desktop/Environments/Bynry-360/lib/python3.6/site-packages/django/template/base.py", line 903, in render_annotated
    return self.render(context)
  File "/home/admin1/Desktop/Environments/Bynry-360/lib/python3.6/site-packages/django/template/loader_tags.py", line 150, in render
    return compiled_parent._render(context)
  File "/home/admin1/Desktop/Environments/Bynry-360/lib/python3.6/site-packages/django/template/base.py", line 163, in _render
    return self.nodelist.render(context)
  File "/home/admin1/Desktop/Environments/Bynry-360/lib/python3.6/site-packages/django/template/base.py", line 936, in render
    bit = node.render_annotated(context)
  File "/home/admin1/Desktop/Environments/Bynry-360/lib/python3.6/site-packages/django/template/base.py", line 903, in render_annotated
    return self.render(context)
  File "/home/admin1/Desktop/Environments/Bynry-360/lib/python3.6/site-packages/django/template/loader_tags.py", line 150, in render
    return compiled_parent._render(context)
  File "/home/admin1/Desktop/Environments/Bynry-360/lib/python3.6/site-packages/django/template/base.py", line 163, in _render
    return self.nodelist.render(context)
  File "/home/admin1/Desktop/Environments/Bynry-360/lib/python3.6/site-packages/django/template/base.py", line 936, in render
    bit = node.render_annotated(context)
  File "/home/admin1/Desktop/Environments/Bynry-360/lib/python3.6/site-packages/django/template/base.py", line 903, in render_annotated
    return self.render(context)
  File "/home/admin1/Desktop/Environments/Bynry-360/lib/python3.6/site-packages/django/template/loader_tags.py", line 62, in render
    result = block.nodelist.render(context)
  File "/home/admin1/Desktop/Environments/Bynry-360/lib/python3.6/site-packages/django/template/base.py", line 936, in render
    bit = node.render_annotated(context)
  File "/home/admin1/Desktop/Environments/Bynry-360/lib/python3.6/site-packages/django/template/base.py", line 903, in render_annotated
    return self.render(context)
  File "/home/admin1/Desktop/Environments/Bynry-360/lib/python3.6/site-packages/django/template/loader_tags.py", line 62, in render
    result = block.nodelist.render(context)
  File "/home/admin1/Desktop/Environments/Bynry-360/lib/python3.6/site-packages/django/template/base.py", line 936, in render
    bit = node.render_annotated(context)
  File "/home/admin1/Desktop/Environments/Bynry-360/lib/python3.6/site-packages/django/template/base.py", line 903, in render_annotated
    return self.render(context)
  File "/home/admin1/Desktop/Environments/Bynry-360/lib/python3.6/site-packages/django/template/defaulttags.py", line 209, in render
    nodelist.append(node.render_annotated(context))
  File "/home/admin1/Desktop/Environments/Bynry-360/lib/python3.6/site-packages/django/template/base.py", line 903, in render_annotated
    return self.render(context)
  File "/home/admin1/Desktop/Environments/Bynry-360/lib/python3.6/site-packages/django/template/loader_tags.py", line 188, in render
    return template.render(context)
  File "/home/admin1/Desktop/Environments/Bynry-360/lib/python3.6/site-packages/django/template/base.py", line 173, in render
    return self._render(context)
  File "/home/admin1/Desktop/Environments/Bynry-360/lib/python3.6/site-packages/django/template/base.py", line 163, in _render
    return self.nodelist.render(context)
  File "/home/admin1/Desktop/Environments/Bynry-360/lib/python3.6/site-packages/django/template/base.py", line 936, in render
    bit = node.render_annotated(context)
  File "/home/admin1/Desktop/Environments/Bynry-360/lib/python3.6/site-packages/django/template/base.py", line 903, in render_annotated
    return self.render(context)
  File "/home/admin1/Desktop/Environments/Bynry-360/lib/python3.6/site-packages/django/template/defaulttags.py", line 209, in render
    nodelist.append(node.render_annotated(context))
  File "/home/admin1/Desktop/Environments/Bynry-360/lib/python3.6/site-packages/django/template/base.py", line 903, in render_annotated
    return self.render(context)
  File "/home/admin1/Desktop/Environments/Bynry-360/lib/python3.6/site-packages/django/template/defaulttags.py", line 209, in render
    nodelist.append(node.render_annotated(context))
  File "/home/admin1/Desktop/Environments/Bynry-360/lib/python3.6/site-packages/django/template/base.py", line 903, in render_annotated
    return self.render(context)
  File "/home/admin1/Desktop/Environments/Bynry-360/lib/python3.6/site-packages/django/template/defaulttags.py", line 309, in render
    return nodelist.render(context)
  File "/home/admin1/Desktop/Environments/Bynry-360/lib/python3.6/site-packages/django/template/base.py", line 936, in render
    bit = node.render_annotated(context)
  File "/home/admin1/Desktop/Environments/Bynry-360/lib/python3.6/site-packages/django/template/base.py", line 903, in render_annotated
    return self.render(context)
  File "/home/admin1/Desktop/Environments/Bynry-360/lib/python3.6/site-packages/django/template/defaulttags.py", line 309, in render
    return nodelist.render(context)
  File "/home/admin1/Desktop/Environments/Bynry-360/lib/python3.6/site-packages/django/template/base.py", line 936, in render
    bit = node.render_annotated(context)
  File "/home/admin1/Desktop/Environments/Bynry-360/lib/python3.6/site-packages/django/template/base.py", line 903, in render_annotated
    return self.render(context)
  File "/home/admin1/Desktop/Environments/Bynry-360/lib/python3.6/site-packages/django/template/base.py", line 992, in render
    return render_value_in_context(output, context)
  File "/home/admin1/Desktop/Environments/Bynry-360/lib/python3.6/site-packages/django/template/base.py", line 971, in render_value_in_context
    value = str(value)
  File "/home/admin1/Desktop/Environments/Bynry-360/lib/python3.6/site-packages/django/utils/html.py", line 373, in <lambda>
    klass.__str__ = lambda self: mark_safe(klass_str(self))
  File "/home/admin1/Desktop/Environments/Bynry-360/lib/python3.6/site-packages/django/forms/boundfield.py", line 33, in __str__
    return self.as_widget()
  File "/home/admin1/Desktop/Environments/Bynry-360/lib/python3.6/site-packages/django/forms/boundfield.py", line 96, in as_widget
    renderer=self.form.renderer,
  File "/home/admin1/Desktop/Environments/Bynry-360/lib/python3.6/site-packages/django/forms/widgets.py", line 241, in render
    context = self.get_context(name, value, attrs)
  File "/home/admin1/Desktop/Environments/Bynry-360/lib/python3.6/site-packages/django/contrib/admin/widgets.py", line 91, in get_context
    context = super().get_context(name, value, attrs)
  File "/home/admin1/Desktop/Environments/Bynry-360/lib/python3.6/site-packages/django/forms/widgets.py", line 817, in get_context
    value = self.decompress(value)
  File "/home/admin1/Desktop/Environments/Bynry-360/lib/python3.6/site-packages/django/forms/widgets.py", line 905, in decompress
    value = to_current_timezone(value)
  File "/home/admin1/Desktop/Environments/Bynry-360/lib/python3.6/site-packages/django/forms/utils.py", line 176, in to_current_timezone
    if settings.USE_TZ and value is not None and timezone.is_aware(value):
  File "/home/admin1/Desktop/Environments/Bynry-360/lib/python3.6/site-packages/django/utils/timezone.py", line 248, in is_aware
    return value.utcoffset() is not None
AttributeError: 'datetime.date' object has no attribute 'utcoffset'
"GET /admin/registration/registration/3/change/ HTTP/1.1" 500 570865
"GET /admin/registration/registration/ HTTP/1.1" 200 4881
Internal Server Error: /admin/registration/registration/1/change/
Traceback (most recent call last):
  File "/home/admin1/Desktop/Environments/Bynry-360/lib/python3.6/site-packages/django/core/handlers/exception.py", line 34, in inner
    response = get_response(request)
  File "/home/admin1/Desktop/Environments/Bynry-360/lib/python3.6/site-packages/django/core/handlers/base.py", line 145, in _get_response
    response = self.process_exception_by_middleware(e, request)
  File "/home/admin1/Desktop/Environments/Bynry-360/lib/python3.6/site-packages/django/core/handlers/base.py", line 143, in _get_response
    response = response.render()
  File "/home/admin1/Desktop/Environments/Bynry-360/lib/python3.6/site-packages/django/template/response.py", line 105, in render
    self.content = self.rendered_content
  File "/home/admin1/Desktop/Environments/Bynry-360/lib/python3.6/site-packages/django/template/response.py", line 83, in rendered_content
    return template.render(context, self._request)
  File "/home/admin1/Desktop/Environments/Bynry-360/lib/python3.6/site-packages/django/template/backends/django.py", line 61, in render
    return self.template.render(context)
  File "/home/admin1/Desktop/Environments/Bynry-360/lib/python3.6/site-packages/django/template/base.py", line 171, in render
    return self._render(context)
  File "/home/admin1/Desktop/Environments/Bynry-360/lib/python3.6/site-packages/django/template/base.py", line 163, in _render
    return self.nodelist.render(context)
  File "/home/admin1/Desktop/Environments/Bynry-360/lib/python3.6/site-packages/django/template/base.py", line 936, in render
    bit = node.render_annotated(context)
  File "/home/admin1/Desktop/Environments/Bynry-360/lib/python3.6/site-packages/django/template/base.py", line 903, in render_annotated
    return self.render(context)
  File "/home/admin1/Desktop/Environments/Bynry-360/lib/python3.6/site-packages/django/template/loader_tags.py", line 150, in render
    return compiled_parent._render(context)
  File "/home/admin1/Desktop/Environments/Bynry-360/lib/python3.6/site-packages/django/template/base.py", line 163, in _render
    return self.nodelist.render(context)
  File "/home/admin1/Desktop/Environments/Bynry-360/lib/python3.6/site-packages/django/template/base.py", line 936, in render
    bit = node.render_annotated(context)
  File "/home/admin1/Desktop/Environments/Bynry-360/lib/python3.6/site-packages/django/template/base.py", line 903, in render_annotated
    return self.render(context)
  File "/home/admin1/Desktop/Environments/Bynry-360/lib/python3.6/site-packages/django/template/loader_tags.py", line 150, in render
    return compiled_parent._render(context)
  File "/home/admin1/Desktop/Environments/Bynry-360/lib/python3.6/site-packages/django/template/base.py", line 163, in _render
    return self.nodelist.render(context)
  File "/home/admin1/Desktop/Environments/Bynry-360/lib/python3.6/site-packages/django/template/base.py", line 936, in render
    bit = node.render_annotated(context)
  File "/home/admin1/Desktop/Environments/Bynry-360/lib/python3.6/site-packages/django/template/base.py", line 903, in render_annotated
    return self.render(context)
  File "/home/admin1/Desktop/Environments/Bynry-360/lib/python3.6/site-packages/django/template/loader_tags.py", line 62, in render
    result = block.nodelist.render(context)
  File "/home/admin1/Desktop/Environments/Bynry-360/lib/python3.6/site-packages/django/template/base.py", line 936, in render
    bit = node.render_annotated(context)
  File "/home/admin1/Desktop/Environments/Bynry-360/lib/python3.6/site-packages/django/template/base.py", line 903, in render_annotated
    return self.render(context)
  File "/home/admin1/Desktop/Environments/Bynry-360/lib/python3.6/site-packages/django/template/loader_tags.py", line 62, in render
    result = block.nodelist.render(context)
  File "/home/admin1/Desktop/Environments/Bynry-360/lib/python3.6/site-packages/django/template/base.py", line 936, in render
    bit = node.render_annotated(context)
  File "/home/admin1/Desktop/Environments/Bynry-360/lib/python3.6/site-packages/django/template/base.py", line 903, in render_annotated
    return self.render(context)
  File "/home/admin1/Desktop/Environments/Bynry-360/lib/python3.6/site-packages/django/template/defaulttags.py", line 209, in render
    nodelist.append(node.render_annotated(context))
  File "/home/admin1/Desktop/Environments/Bynry-360/lib/python3.6/site-packages/django/template/base.py", line 903, in render_annotated
    return self.render(context)
  File "/home/admin1/Desktop/Environments/Bynry-360/lib/python3.6/site-packages/django/template/loader_tags.py", line 188, in render
    return template.render(context)
  File "/home/admin1/Desktop/Environments/Bynry-360/lib/python3.6/site-packages/django/template/base.py", line 173, in render
    return self._render(context)
  File "/home/admin1/Desktop/Environments/Bynry-360/lib/python3.6/site-packages/django/template/base.py", line 163, in _render
    return self.nodelist.render(context)
  File "/home/admin1/Desktop/Environments/Bynry-360/lib/python3.6/site-packages/django/template/base.py", line 936, in render
    bit = node.render_annotated(context)
  File "/home/admin1/Desktop/Environments/Bynry-360/lib/python3.6/site-packages/django/template/base.py", line 903, in render_annotated
    return self.render(context)
  File "/home/admin1/Desktop/Environments/Bynry-360/lib/python3.6/site-packages/django/template/defaulttags.py", line 209, in render
    nodelist.append(node.render_annotated(context))
  File "/home/admin1/Desktop/Environments/Bynry-360/lib/python3.6/site-packages/django/template/base.py", line 903, in render_annotated
    return self.render(context)
  File "/home/admin1/Desktop/Environments/Bynry-360/lib/python3.6/site-packages/django/template/defaulttags.py", line 209, in render
    nodelist.append(node.render_annotated(context))
  File "/home/admin1/Desktop/Environments/Bynry-360/lib/python3.6/site-packages/django/template/base.py", line 903, in render_annotated
    return self.render(context)
  File "/home/admin1/Desktop/Environments/Bynry-360/lib/python3.6/site-packages/django/template/defaulttags.py", line 309, in render
    return nodelist.render(context)
  File "/home/admin1/Desktop/Environments/Bynry-360/lib/python3.6/site-packages/django/template/base.py", line 936, in render
    bit = node.render_annotated(context)
  File "/home/admin1/Desktop/Environments/Bynry-360/lib/python3.6/site-packages/django/template/base.py", line 903, in render_annotated
    return self.render(context)
  File "/home/admin1/Desktop/Environments/Bynry-360/lib/python3.6/site-packages/django/template/defaulttags.py", line 309, in render
    return nodelist.render(context)
  File "/home/admin1/Desktop/Environments/Bynry-360/lib/python3.6/site-packages/django/template/base.py", line 936, in render
    bit = node.render_annotated(context)
  File "/home/admin1/Desktop/Environments/Bynry-360/lib/python3.6/site-packages/django/template/base.py", line 903, in render_annotated
    return self.render(context)
  File "/home/admin1/Desktop/Environments/Bynry-360/lib/python3.6/site-packages/django/template/base.py", line 992, in render
    return render_value_in_context(output, context)
  File "/home/admin1/Desktop/Environments/Bynry-360/lib/python3.6/site-packages/django/template/base.py", line 971, in render_value_in_context
    value = str(value)
  File "/home/admin1/Desktop/Environments/Bynry-360/lib/python3.6/site-packages/django/utils/html.py", line 373, in <lambda>
    klass.__str__ = lambda self: mark_safe(klass_str(self))
  File "/home/admin1/Desktop/Environments/Bynry-360/lib/python3.6/site-packages/django/forms/boundfield.py", line 33, in __str__
    return self.as_widget()
  File "/home/admin1/Desktop/Environments/Bynry-360/lib/python3.6/site-packages/django/forms/boundfield.py", line 96, in as_widget
    renderer=self.form.renderer,
  File "/home/admin1/Desktop/Environments/Bynry-360/lib/python3.6/site-packages/django/forms/widgets.py", line 241, in render
    context = self.get_context(name, value, attrs)
  File "/home/admin1/Desktop/Environments/Bynry-360/lib/python3.6/site-packages/django/contrib/admin/widgets.py", line 91, in get_context
    context = super().get_context(name, value, attrs)
  File "/home/admin1/Desktop/Environments/Bynry-360/lib/python3.6/site-packages/django/forms/widgets.py", line 817, in get_context
    value = self.decompress(value)
  File "/home/admin1/Desktop/Environments/Bynry-360/lib/python3.6/site-packages/django/forms/widgets.py", line 905, in decompress
    value = to_current_timezone(value)
  File "/home/admin1/Desktop/Environments/Bynry-360/lib/python3.6/site-packages/django/forms/utils.py", line 176, in to_current_timezone
    if settings.USE_TZ and value is not None and timezone.is_aware(value):
  File "/home/admin1/Desktop/Environments/Bynry-360/lib/python3.6/site-packages/django/utils/timezone.py", line 248, in is_aware
    return value.utcoffset() is not None
AttributeError: 'datetime.date' object has no attribute 'utcoffset'
"GET /admin/registration/registration/1/change/ HTTP/1.1" 500 570864
"GET /admin/registration/registration/ HTTP/1.1" 200 4881
"POST /admin/registration/registration/ HTTP/1.1" 200 3709
"POST /admin/registration/registration/ HTTP/1.1" 302 0
"GET /admin/registration/registration/ HTTP/1.1" 200 3364
"GET /admin/jsi18n/ HTTP/1.1" 200 3223
/home/admin1/yy/Smart360-app/api/v1/registration/models/registrations.py changed, reloading.
Watching for file changes with StatReloader
/home/admin1/yy/Smart360-app/api/v1/registration/models/registrations.py changed, reloading.
Watching for file changes with StatReloader
Internal Server Error: /api/v1/registration/list
Traceback (most recent call last):
  File "/home/admin1/Desktop/Environments/Bynry-360/lib/python3.6/site-packages/django/core/handlers/exception.py", line 34, in inner
    response = get_response(request)
  File "/home/admin1/Desktop/Environments/Bynry-360/lib/python3.6/site-packages/django/core/handlers/base.py", line 115, in _get_response
    response = self.process_exception_by_middleware(e, request)
  File "/home/admin1/Desktop/Environments/Bynry-360/lib/python3.6/site-packages/django/core/handlers/base.py", line 113, in _get_response
    response = wrapped_callback(request, *callback_args, **callback_kwargs)
  File "/home/admin1/Desktop/Environments/Bynry-360/lib/python3.6/site-packages/django/views/decorators/csrf.py", line 54, in wrapped_view
    return view_func(*args, **kwargs)
  File "/home/admin1/Desktop/Environments/Bynry-360/lib/python3.6/site-packages/django/views/generic/base.py", line 71, in view
    return self.dispatch(request, *args, **kwargs)
  File "/home/admin1/Desktop/Environments/Bynry-360/lib/python3.6/site-packages/rest_framework/views.py", line 505, in dispatch
    response = self.handle_exception(exc)
  File "/home/admin1/Desktop/Environments/Bynry-360/lib/python3.6/site-packages/rest_framework/views.py", line 465, in handle_exception
    self.raise_uncaught_exception(exc)
  File "/home/admin1/Desktop/Environments/Bynry-360/lib/python3.6/site-packages/rest_framework/views.py", line 476, in raise_uncaught_exception
    raise exc
  File "/home/admin1/Desktop/Environments/Bynry-360/lib/python3.6/site-packages/rest_framework/views.py", line 502, in dispatch
    response = handler(request, *args, **kwargs)
  File "/home/admin1/Desktop/Environments/Bynry-360/lib/python3.6/site-packages/rest_framework/generics.py", line 199, in get
    return self.list(request, *args, **kwargs)
  File "/home/admin1/Desktop/Environments/Bynry-360/lib/python3.6/site-packages/rest_framework/mixins.py", line 43, in list
    return self.get_paginated_response(serializer.data)
  File "/home/admin1/Desktop/Environments/Bynry-360/lib/python3.6/site-packages/rest_framework/serializers.py", line 760, in data
    ret = super().data
  File "/home/admin1/Desktop/Environments/Bynry-360/lib/python3.6/site-packages/rest_framework/serializers.py", line 260, in data
    self._data = self.to_representation(self.instance)
  File "/home/admin1/Desktop/Environments/Bynry-360/lib/python3.6/site-packages/rest_framework/serializers.py", line 678, in to_representation
    self.child.to_representation(item) for item in iterable
  File "/home/admin1/Desktop/Environments/Bynry-360/lib/python3.6/site-packages/rest_framework/serializers.py", line 678, in <listcomp>
    self.child.to_representation(item) for item in iterable
  File "/home/admin1/Desktop/Environments/Bynry-360/lib/python3.6/site-packages/rest_framework/serializers.py", line 529, in to_representation
    ret[field.field_name] = field.to_representation(attribute)
  File "/home/admin1/Desktop/Environments/Bynry-360/lib/python3.6/site-packages/rest_framework/fields.py", line 1255, in to_representation
    value = self.enforce_timezone(value)
  File "/home/admin1/Desktop/Environments/Bynry-360/lib/python3.6/site-packages/rest_framework/fields.py", line 1203, in enforce_timezone
    if timezone.is_aware(value):
  File "/home/admin1/Desktop/Environments/Bynry-360/lib/python3.6/site-packages/django/utils/timezone.py", line 248, in is_aware
    return value.utcoffset() is not None
AttributeError: 'datetime.date' object has no attribute 'utcoffset'
"GET /api/v1/registration/list HTTP/1.1" 500 19254
Internal Server Error: /api/v1/registration/list
Traceback (most recent call last):
  File "/home/admin1/Desktop/Environments/Bynry-360/lib/python3.6/site-packages/django/core/handlers/exception.py", line 34, in inner
    response = get_response(request)
  File "/home/admin1/Desktop/Environments/Bynry-360/lib/python3.6/site-packages/django/core/handlers/base.py", line 115, in _get_response
    response = self.process_exception_by_middleware(e, request)
  File "/home/admin1/Desktop/Environments/Bynry-360/lib/python3.6/site-packages/django/core/handlers/base.py", line 113, in _get_response
    response = wrapped_callback(request, *callback_args, **callback_kwargs)
  File "/home/admin1/Desktop/Environments/Bynry-360/lib/python3.6/site-packages/django/views/decorators/csrf.py", line 54, in wrapped_view
    return view_func(*args, **kwargs)
  File "/home/admin1/Desktop/Environments/Bynry-360/lib/python3.6/site-packages/django/views/generic/base.py", line 71, in view
    return self.dispatch(request, *args, **kwargs)
  File "/home/admin1/Desktop/Environments/Bynry-360/lib/python3.6/site-packages/rest_framework/views.py", line 505, in dispatch
    response = self.handle_exception(exc)
  File "/home/admin1/Desktop/Environments/Bynry-360/lib/python3.6/site-packages/rest_framework/views.py", line 465, in handle_exception
    self.raise_uncaught_exception(exc)
  File "/home/admin1/Desktop/Environments/Bynry-360/lib/python3.6/site-packages/rest_framework/views.py", line 476, in raise_uncaught_exception
    raise exc
  File "/home/admin1/Desktop/Environments/Bynry-360/lib/python3.6/site-packages/rest_framework/views.py", line 502, in dispatch
    response = handler(request, *args, **kwargs)
  File "/home/admin1/Desktop/Environments/Bynry-360/lib/python3.6/site-packages/rest_framework/generics.py", line 199, in get
    return self.list(request, *args, **kwargs)
  File "/home/admin1/Desktop/Environments/Bynry-360/lib/python3.6/site-packages/rest_framework/mixins.py", line 43, in list
    return self.get_paginated_response(serializer.data)
  File "/home/admin1/Desktop/Environments/Bynry-360/lib/python3.6/site-packages/rest_framework/serializers.py", line 760, in data
    ret = super().data
  File "/home/admin1/Desktop/Environments/Bynry-360/lib/python3.6/site-packages/rest_framework/serializers.py", line 260, in data
    self._data = self.to_representation(self.instance)
  File "/home/admin1/Desktop/Environments/Bynry-360/lib/python3.6/site-packages/rest_framework/serializers.py", line 678, in to_representation
    self.child.to_representation(item) for item in iterable
  File "/home/admin1/Desktop/Environments/Bynry-360/lib/python3.6/site-packages/rest_framework/serializers.py", line 678, in <listcomp>
    self.child.to_representation(item) for item in iterable
  File "/home/admin1/Desktop/Environments/Bynry-360/lib/python3.6/site-packages/rest_framework/serializers.py", line 529, in to_representation
    ret[field.field_name] = field.to_representation(attribute)
  File "/home/admin1/Desktop/Environments/Bynry-360/lib/python3.6/site-packages/rest_framework/fields.py", line 1255, in to_representation
    value = self.enforce_timezone(value)
  File "/home/admin1/Desktop/Environments/Bynry-360/lib/python3.6/site-packages/rest_framework/fields.py", line 1203, in enforce_timezone
    if timezone.is_aware(value):
  File "/home/admin1/Desktop/Environments/Bynry-360/lib/python3.6/site-packages/django/utils/timezone.py", line 248, in is_aware
    return value.utcoffset() is not None
AttributeError: 'datetime.date' object has no attribute 'utcoffset'
"GET /api/v1/registration/list HTTP/1.1" 500 19254
/home/admin1/yy/Smart360-app/api/v1/registration/serializers/registration.py changed, reloading.
Watching for file changes with StatReloader
"GET /api/v1/registration/list HTTP/1.1" 200 988
"GET /api/v1/registration/c91605d8-ba11-4a87-9d12-ac43814952a1 HTTP/1.1" 200 568
Internal Server Error: /api/v1/registration/
Traceback (most recent call last):
  File "/home/admin1/yy/Smart360-app/api/v1/registration/views/registrations.py", line 97, in post
    registration_obj = serializer.create(serializer.validated_data, user)
  File "/home/admin1/yy/Smart360-app/api/v1/registration/serializers/registration.py", line 74, in create
    validated_data =  set_validated_data(validated_data)
  File "/home/admin1/yy/Smart360-app/api/v1/registration/views/common_functions.py", line 26, in set_validated_data
    validated_data["status_id"] = registration_status.id
AttributeError: 'bool' object has no attribute 'id'

During handling of the above exception, another exception occurred:

Traceback (most recent call last):
  File "/home/admin1/Desktop/Environments/Bynry-360/lib/python3.6/site-packages/django/core/handlers/exception.py", line 34, in inner
    response = get_response(request)
  File "/home/admin1/Desktop/Environments/Bynry-360/lib/python3.6/site-packages/django/core/handlers/base.py", line 115, in _get_response
    response = self.process_exception_by_middleware(e, request)
  File "/home/admin1/Desktop/Environments/Bynry-360/lib/python3.6/site-packages/django/core/handlers/base.py", line 113, in _get_response
    response = wrapped_callback(request, *callback_args, **callback_kwargs)
  File "/home/admin1/Desktop/Environments/Bynry-360/lib/python3.6/site-packages/django/views/decorators/csrf.py", line 54, in wrapped_view
    return view_func(*args, **kwargs)
  File "/home/admin1/Desktop/Environments/Bynry-360/lib/python3.6/site-packages/django/views/generic/base.py", line 71, in view
    return self.dispatch(request, *args, **kwargs)
  File "/home/admin1/Desktop/Environments/Bynry-360/lib/python3.6/site-packages/rest_framework/views.py", line 505, in dispatch
    response = self.handle_exception(exc)
  File "/home/admin1/Desktop/Environments/Bynry-360/lib/python3.6/site-packages/rest_framework/views.py", line 465, in handle_exception
    self.raise_uncaught_exception(exc)
  File "/home/admin1/Desktop/Environments/Bynry-360/lib/python3.6/site-packages/rest_framework/views.py", line 476, in raise_uncaught_exception
    raise exc
  File "/home/admin1/Desktop/Environments/Bynry-360/lib/python3.6/site-packages/rest_framework/views.py", line 502, in dispatch
    response = handler(request, *args, **kwargs)
  File "/home/admin1/yy/Smart360-app/api/v1/registration/views/registrations.py", line 121, in post
    traceback.print_exc(e)
  File "/usr/lib/python3.6/traceback.py", line 163, in print_exc
    print_exception(*sys.exc_info(), limit=limit, file=file, chain=chain)
  File "/usr/lib/python3.6/traceback.py", line 104, in print_exception
    type(value), value, tb, limit=limit).format(chain=chain):
  File "/usr/lib/python3.6/traceback.py", line 509, in __init__
    capture_locals=capture_locals)
  File "/usr/lib/python3.6/traceback.py", line 338, in extract
    if limit >= 0:
TypeError: '>=' not supported between instances of 'AttributeError' and 'int'
"POST /api/v1/registration/ HTTP/1.1" 500 18648
"POST /api/v1/registration/ HTTP/1.1" 201 555
"GET /admin/registration/registration/ HTTP/1.1" 200 5113
"GET /admin/jsi18n/ HTTP/1.1" 200 3223
Internal Server Error: /admin/registration/registration/1/change/
Traceback (most recent call last):
  File "/home/admin1/Desktop/Environments/Bynry-360/lib/python3.6/site-packages/django/core/handlers/exception.py", line 34, in inner
    response = get_response(request)
  File "/home/admin1/Desktop/Environments/Bynry-360/lib/python3.6/site-packages/django/core/handlers/base.py", line 145, in _get_response
    response = self.process_exception_by_middleware(e, request)
  File "/home/admin1/Desktop/Environments/Bynry-360/lib/python3.6/site-packages/django/core/handlers/base.py", line 143, in _get_response
    response = response.render()
  File "/home/admin1/Desktop/Environments/Bynry-360/lib/python3.6/site-packages/django/template/response.py", line 105, in render
    self.content = self.rendered_content
  File "/home/admin1/Desktop/Environments/Bynry-360/lib/python3.6/site-packages/django/template/response.py", line 83, in rendered_content
    return template.render(context, self._request)
  File "/home/admin1/Desktop/Environments/Bynry-360/lib/python3.6/site-packages/django/template/backends/django.py", line 61, in render
    return self.template.render(context)
  File "/home/admin1/Desktop/Environments/Bynry-360/lib/python3.6/site-packages/django/template/base.py", line 171, in render
    return self._render(context)
  File "/home/admin1/Desktop/Environments/Bynry-360/lib/python3.6/site-packages/django/template/base.py", line 163, in _render
    return self.nodelist.render(context)
  File "/home/admin1/Desktop/Environments/Bynry-360/lib/python3.6/site-packages/django/template/base.py", line 936, in render
    bit = node.render_annotated(context)
  File "/home/admin1/Desktop/Environments/Bynry-360/lib/python3.6/site-packages/django/template/base.py", line 903, in render_annotated
    return self.render(context)
  File "/home/admin1/Desktop/Environments/Bynry-360/lib/python3.6/site-packages/django/template/loader_tags.py", line 150, in render
    return compiled_parent._render(context)
  File "/home/admin1/Desktop/Environments/Bynry-360/lib/python3.6/site-packages/django/template/base.py", line 163, in _render
    return self.nodelist.render(context)
  File "/home/admin1/Desktop/Environments/Bynry-360/lib/python3.6/site-packages/django/template/base.py", line 936, in render
    bit = node.render_annotated(context)
  File "/home/admin1/Desktop/Environments/Bynry-360/lib/python3.6/site-packages/django/template/base.py", line 903, in render_annotated
    return self.render(context)
  File "/home/admin1/Desktop/Environments/Bynry-360/lib/python3.6/site-packages/django/template/loader_tags.py", line 150, in render
    return compiled_parent._render(context)
  File "/home/admin1/Desktop/Environments/Bynry-360/lib/python3.6/site-packages/django/template/base.py", line 163, in _render
    return self.nodelist.render(context)
  File "/home/admin1/Desktop/Environments/Bynry-360/lib/python3.6/site-packages/django/template/base.py", line 936, in render
    bit = node.render_annotated(context)
  File "/home/admin1/Desktop/Environments/Bynry-360/lib/python3.6/site-packages/django/template/base.py", line 903, in render_annotated
    return self.render(context)
  File "/home/admin1/Desktop/Environments/Bynry-360/lib/python3.6/site-packages/django/template/loader_tags.py", line 62, in render
    result = block.nodelist.render(context)
  File "/home/admin1/Desktop/Environments/Bynry-360/lib/python3.6/site-packages/django/template/base.py", line 936, in render
    bit = node.render_annotated(context)
  File "/home/admin1/Desktop/Environments/Bynry-360/lib/python3.6/site-packages/django/template/base.py", line 903, in render_annotated
    return self.render(context)
  File "/home/admin1/Desktop/Environments/Bynry-360/lib/python3.6/site-packages/django/template/loader_tags.py", line 62, in render
    result = block.nodelist.render(context)
  File "/home/admin1/Desktop/Environments/Bynry-360/lib/python3.6/site-packages/django/template/base.py", line 936, in render
    bit = node.render_annotated(context)
  File "/home/admin1/Desktop/Environments/Bynry-360/lib/python3.6/site-packages/django/template/base.py", line 903, in render_annotated
    return self.render(context)
  File "/home/admin1/Desktop/Environments/Bynry-360/lib/python3.6/site-packages/django/template/defaulttags.py", line 209, in render
    nodelist.append(node.render_annotated(context))
  File "/home/admin1/Desktop/Environments/Bynry-360/lib/python3.6/site-packages/django/template/base.py", line 903, in render_annotated
    return self.render(context)
  File "/home/admin1/Desktop/Environments/Bynry-360/lib/python3.6/site-packages/django/template/loader_tags.py", line 188, in render
    return template.render(context)
  File "/home/admin1/Desktop/Environments/Bynry-360/lib/python3.6/site-packages/django/template/base.py", line 173, in render
    return self._render(context)
  File "/home/admin1/Desktop/Environments/Bynry-360/lib/python3.6/site-packages/django/template/base.py", line 163, in _render
    return self.nodelist.render(context)
  File "/home/admin1/Desktop/Environments/Bynry-360/lib/python3.6/site-packages/django/template/base.py", line 936, in render
    bit = node.render_annotated(context)
  File "/home/admin1/Desktop/Environments/Bynry-360/lib/python3.6/site-packages/django/template/base.py", line 903, in render_annotated
    return self.render(context)
  File "/home/admin1/Desktop/Environments/Bynry-360/lib/python3.6/site-packages/django/template/defaulttags.py", line 209, in render
    nodelist.append(node.render_annotated(context))
  File "/home/admin1/Desktop/Environments/Bynry-360/lib/python3.6/site-packages/django/template/base.py", line 903, in render_annotated
    return self.render(context)
  File "/home/admin1/Desktop/Environments/Bynry-360/lib/python3.6/site-packages/django/template/defaulttags.py", line 209, in render
    nodelist.append(node.render_annotated(context))
  File "/home/admin1/Desktop/Environments/Bynry-360/lib/python3.6/site-packages/django/template/base.py", line 903, in render_annotated
    return self.render(context)
  File "/home/admin1/Desktop/Environments/Bynry-360/lib/python3.6/site-packages/django/template/defaulttags.py", line 309, in render
    return nodelist.render(context)
  File "/home/admin1/Desktop/Environments/Bynry-360/lib/python3.6/site-packages/django/template/base.py", line 936, in render
    bit = node.render_annotated(context)
  File "/home/admin1/Desktop/Environments/Bynry-360/lib/python3.6/site-packages/django/template/base.py", line 903, in render_annotated
    return self.render(context)
  File "/home/admin1/Desktop/Environments/Bynry-360/lib/python3.6/site-packages/django/template/defaulttags.py", line 309, in render
    return nodelist.render(context)
  File "/home/admin1/Desktop/Environments/Bynry-360/lib/python3.6/site-packages/django/template/base.py", line 936, in render
    bit = node.render_annotated(context)
  File "/home/admin1/Desktop/Environments/Bynry-360/lib/python3.6/site-packages/django/template/base.py", line 903, in render_annotated
    return self.render(context)
  File "/home/admin1/Desktop/Environments/Bynry-360/lib/python3.6/site-packages/django/template/base.py", line 992, in render
    return render_value_in_context(output, context)
  File "/home/admin1/Desktop/Environments/Bynry-360/lib/python3.6/site-packages/django/template/base.py", line 971, in render_value_in_context
    value = str(value)
  File "/home/admin1/Desktop/Environments/Bynry-360/lib/python3.6/site-packages/django/utils/html.py", line 373, in <lambda>
    klass.__str__ = lambda self: mark_safe(klass_str(self))
  File "/home/admin1/Desktop/Environments/Bynry-360/lib/python3.6/site-packages/django/forms/boundfield.py", line 33, in __str__
    return self.as_widget()
  File "/home/admin1/Desktop/Environments/Bynry-360/lib/python3.6/site-packages/django/forms/boundfield.py", line 96, in as_widget
    renderer=self.form.renderer,
  File "/home/admin1/Desktop/Environments/Bynry-360/lib/python3.6/site-packages/django/forms/widgets.py", line 241, in render
    context = self.get_context(name, value, attrs)
  File "/home/admin1/Desktop/Environments/Bynry-360/lib/python3.6/site-packages/django/contrib/admin/widgets.py", line 91, in get_context
    context = super().get_context(name, value, attrs)
  File "/home/admin1/Desktop/Environments/Bynry-360/lib/python3.6/site-packages/django/forms/widgets.py", line 817, in get_context
    value = self.decompress(value)
  File "/home/admin1/Desktop/Environments/Bynry-360/lib/python3.6/site-packages/django/forms/widgets.py", line 905, in decompress
    value = to_current_timezone(value)
  File "/home/admin1/Desktop/Environments/Bynry-360/lib/python3.6/site-packages/django/forms/utils.py", line 176, in to_current_timezone
    if settings.USE_TZ and value is not None and timezone.is_aware(value):
  File "/home/admin1/Desktop/Environments/Bynry-360/lib/python3.6/site-packages/django/utils/timezone.py", line 248, in is_aware
    return value.utcoffset() is not None
AttributeError: 'datetime.date' object has no attribute 'utcoffset'
"GET /admin/registration/registration/1/change/ HTTP/1.1" 500 571012
/home/admin1/yy/Smart360-app/api/v1/registration/models/registrations.py changed, reloading.
Watching for file changes with StatReloader
"GET /admin/registration/registration/ HTTP/1.1" 200 5113
"POST /admin/registration/registration/ HTTP/1.1" 200 3863
"POST /admin/registration/registration/ HTTP/1.1" 302 0
"GET /admin/registration/registration/ HTTP/1.1" 200 3364
"GET /admin/jsi18n/ HTTP/1.1" 200 3223
"GET /admin/registration/registration/ HTTP/1.1" 200 4881
"GET /admin/jsi18n/ HTTP/1.1" 200 3223
Internal Server Error: /admin/registration/registration/3/change/
Traceback (most recent call last):
  File "/home/admin1/Desktop/Environments/Bynry-360/lib/python3.6/site-packages/django/core/handlers/exception.py", line 34, in inner
    response = get_response(request)
  File "/home/admin1/Desktop/Environments/Bynry-360/lib/python3.6/site-packages/django/core/handlers/base.py", line 145, in _get_response
    response = self.process_exception_by_middleware(e, request)
  File "/home/admin1/Desktop/Environments/Bynry-360/lib/python3.6/site-packages/django/core/handlers/base.py", line 143, in _get_response
    response = response.render()
  File "/home/admin1/Desktop/Environments/Bynry-360/lib/python3.6/site-packages/django/template/response.py", line 105, in render
    self.content = self.rendered_content
  File "/home/admin1/Desktop/Environments/Bynry-360/lib/python3.6/site-packages/django/template/response.py", line 83, in rendered_content
    return template.render(context, self._request)
  File "/home/admin1/Desktop/Environments/Bynry-360/lib/python3.6/site-packages/django/template/backends/django.py", line 61, in render
    return self.template.render(context)
  File "/home/admin1/Desktop/Environments/Bynry-360/lib/python3.6/site-packages/django/template/base.py", line 171, in render
    return self._render(context)
  File "/home/admin1/Desktop/Environments/Bynry-360/lib/python3.6/site-packages/django/template/base.py", line 163, in _render
    return self.nodelist.render(context)
  File "/home/admin1/Desktop/Environments/Bynry-360/lib/python3.6/site-packages/django/template/base.py", line 936, in render
    bit = node.render_annotated(context)
  File "/home/admin1/Desktop/Environments/Bynry-360/lib/python3.6/site-packages/django/template/base.py", line 903, in render_annotated
    return self.render(context)
  File "/home/admin1/Desktop/Environments/Bynry-360/lib/python3.6/site-packages/django/template/loader_tags.py", line 150, in render
    return compiled_parent._render(context)
  File "/home/admin1/Desktop/Environments/Bynry-360/lib/python3.6/site-packages/django/template/base.py", line 163, in _render
    return self.nodelist.render(context)
  File "/home/admin1/Desktop/Environments/Bynry-360/lib/python3.6/site-packages/django/template/base.py", line 936, in render
    bit = node.render_annotated(context)
  File "/home/admin1/Desktop/Environments/Bynry-360/lib/python3.6/site-packages/django/template/base.py", line 903, in render_annotated
    return self.render(context)
  File "/home/admin1/Desktop/Environments/Bynry-360/lib/python3.6/site-packages/django/template/loader_tags.py", line 150, in render
    return compiled_parent._render(context)
  File "/home/admin1/Desktop/Environments/Bynry-360/lib/python3.6/site-packages/django/template/base.py", line 163, in _render
    return self.nodelist.render(context)
  File "/home/admin1/Desktop/Environments/Bynry-360/lib/python3.6/site-packages/django/template/base.py", line 936, in render
    bit = node.render_annotated(context)
  File "/home/admin1/Desktop/Environments/Bynry-360/lib/python3.6/site-packages/django/template/base.py", line 903, in render_annotated
    return self.render(context)
  File "/home/admin1/Desktop/Environments/Bynry-360/lib/python3.6/site-packages/django/template/loader_tags.py", line 62, in render
    result = block.nodelist.render(context)
  File "/home/admin1/Desktop/Environments/Bynry-360/lib/python3.6/site-packages/django/template/base.py", line 936, in render
    bit = node.render_annotated(context)
  File "/home/admin1/Desktop/Environments/Bynry-360/lib/python3.6/site-packages/django/template/base.py", line 903, in render_annotated
    return self.render(context)
  File "/home/admin1/Desktop/Environments/Bynry-360/lib/python3.6/site-packages/django/template/loader_tags.py", line 62, in render
    result = block.nodelist.render(context)
  File "/home/admin1/Desktop/Environments/Bynry-360/lib/python3.6/site-packages/django/template/base.py", line 936, in render
    bit = node.render_annotated(context)
  File "/home/admin1/Desktop/Environments/Bynry-360/lib/python3.6/site-packages/django/template/base.py", line 903, in render_annotated
    return self.render(context)
  File "/home/admin1/Desktop/Environments/Bynry-360/lib/python3.6/site-packages/django/template/defaulttags.py", line 209, in render
    nodelist.append(node.render_annotated(context))
  File "/home/admin1/Desktop/Environments/Bynry-360/lib/python3.6/site-packages/django/template/base.py", line 903, in render_annotated
    return self.render(context)
  File "/home/admin1/Desktop/Environments/Bynry-360/lib/python3.6/site-packages/django/template/loader_tags.py", line 188, in render
    return template.render(context)
  File "/home/admin1/Desktop/Environments/Bynry-360/lib/python3.6/site-packages/django/template/base.py", line 173, in render
    return self._render(context)
  File "/home/admin1/Desktop/Environments/Bynry-360/lib/python3.6/site-packages/django/template/base.py", line 163, in _render
    return self.nodelist.render(context)
  File "/home/admin1/Desktop/Environments/Bynry-360/lib/python3.6/site-packages/django/template/base.py", line 936, in render
    bit = node.render_annotated(context)
  File "/home/admin1/Desktop/Environments/Bynry-360/lib/python3.6/site-packages/django/template/base.py", line 903, in render_annotated
    return self.render(context)
  File "/home/admin1/Desktop/Environments/Bynry-360/lib/python3.6/site-packages/django/template/defaulttags.py", line 209, in render
    nodelist.append(node.render_annotated(context))
  File "/home/admin1/Desktop/Environments/Bynry-360/lib/python3.6/site-packages/django/template/base.py", line 903, in render_annotated
    return self.render(context)
  File "/home/admin1/Desktop/Environments/Bynry-360/lib/python3.6/site-packages/django/template/defaulttags.py", line 209, in render
    nodelist.append(node.render_annotated(context))
  File "/home/admin1/Desktop/Environments/Bynry-360/lib/python3.6/site-packages/django/template/base.py", line 903, in render_annotated
    return self.render(context)
  File "/home/admin1/Desktop/Environments/Bynry-360/lib/python3.6/site-packages/django/template/defaulttags.py", line 309, in render
    return nodelist.render(context)
  File "/home/admin1/Desktop/Environments/Bynry-360/lib/python3.6/site-packages/django/template/base.py", line 936, in render
    bit = node.render_annotated(context)
  File "/home/admin1/Desktop/Environments/Bynry-360/lib/python3.6/site-packages/django/template/base.py", line 903, in render_annotated
    return self.render(context)
  File "/home/admin1/Desktop/Environments/Bynry-360/lib/python3.6/site-packages/django/template/defaulttags.py", line 309, in render
    return nodelist.render(context)
  File "/home/admin1/Desktop/Environments/Bynry-360/lib/python3.6/site-packages/django/template/base.py", line 936, in render
    bit = node.render_annotated(context)
  File "/home/admin1/Desktop/Environments/Bynry-360/lib/python3.6/site-packages/django/template/base.py", line 903, in render_annotated
    return self.render(context)
  File "/home/admin1/Desktop/Environments/Bynry-360/lib/python3.6/site-packages/django/template/base.py", line 992, in render
    return render_value_in_context(output, context)
  File "/home/admin1/Desktop/Environments/Bynry-360/lib/python3.6/site-packages/django/template/base.py", line 971, in render_value_in_context
    value = str(value)
  File "/home/admin1/Desktop/Environments/Bynry-360/lib/python3.6/site-packages/django/utils/html.py", line 373, in <lambda>
    klass.__str__ = lambda self: mark_safe(klass_str(self))
  File "/home/admin1/Desktop/Environments/Bynry-360/lib/python3.6/site-packages/django/forms/boundfield.py", line 33, in __str__
    return self.as_widget()
  File "/home/admin1/Desktop/Environments/Bynry-360/lib/python3.6/site-packages/django/forms/boundfield.py", line 96, in as_widget
    renderer=self.form.renderer,
  File "/home/admin1/Desktop/Environments/Bynry-360/lib/python3.6/site-packages/django/forms/widgets.py", line 241, in render
    context = self.get_context(name, value, attrs)
  File "/home/admin1/Desktop/Environments/Bynry-360/lib/python3.6/site-packages/django/contrib/admin/widgets.py", line 91, in get_context
    context = super().get_context(name, value, attrs)
  File "/home/admin1/Desktop/Environments/Bynry-360/lib/python3.6/site-packages/django/forms/widgets.py", line 817, in get_context
    value = self.decompress(value)
  File "/home/admin1/Desktop/Environments/Bynry-360/lib/python3.6/site-packages/django/forms/widgets.py", line 905, in decompress
    value = to_current_timezone(value)
  File "/home/admin1/Desktop/Environments/Bynry-360/lib/python3.6/site-packages/django/forms/utils.py", line 176, in to_current_timezone
    if settings.USE_TZ and value is not None and timezone.is_aware(value):
  File "/home/admin1/Desktop/Environments/Bynry-360/lib/python3.6/site-packages/django/utils/timezone.py", line 248, in is_aware
    return value.utcoffset() is not None
AttributeError: 'datetime.date' object has no attribute 'utcoffset'
"GET /admin/registration/registration/3/change/ HTTP/1.1" 500 571013
Internal Server Error: /admin/registration/registration/3/change/
Traceback (most recent call last):
  File "/home/admin1/Desktop/Environments/Bynry-360/lib/python3.6/site-packages/django/core/handlers/exception.py", line 34, in inner
    response = get_response(request)
  File "/home/admin1/Desktop/Environments/Bynry-360/lib/python3.6/site-packages/django/core/handlers/base.py", line 145, in _get_response
    response = self.process_exception_by_middleware(e, request)
  File "/home/admin1/Desktop/Environments/Bynry-360/lib/python3.6/site-packages/django/core/handlers/base.py", line 143, in _get_response
    response = response.render()
  File "/home/admin1/Desktop/Environments/Bynry-360/lib/python3.6/site-packages/django/template/response.py", line 105, in render
    self.content = self.rendered_content
  File "/home/admin1/Desktop/Environments/Bynry-360/lib/python3.6/site-packages/django/template/response.py", line 83, in rendered_content
    return template.render(context, self._request)
  File "/home/admin1/Desktop/Environments/Bynry-360/lib/python3.6/site-packages/django/template/backends/django.py", line 61, in render
    return self.template.render(context)
  File "/home/admin1/Desktop/Environments/Bynry-360/lib/python3.6/site-packages/django/template/base.py", line 171, in render
    return self._render(context)
  File "/home/admin1/Desktop/Environments/Bynry-360/lib/python3.6/site-packages/django/template/base.py", line 163, in _render
    return self.nodelist.render(context)
  File "/home/admin1/Desktop/Environments/Bynry-360/lib/python3.6/site-packages/django/template/base.py", line 936, in render
    bit = node.render_annotated(context)
  File "/home/admin1/Desktop/Environments/Bynry-360/lib/python3.6/site-packages/django/template/base.py", line 903, in render_annotated
    return self.render(context)
  File "/home/admin1/Desktop/Environments/Bynry-360/lib/python3.6/site-packages/django/template/loader_tags.py", line 150, in render
    return compiled_parent._render(context)
  File "/home/admin1/Desktop/Environments/Bynry-360/lib/python3.6/site-packages/django/template/base.py", line 163, in _render
    return self.nodelist.render(context)
  File "/home/admin1/Desktop/Environments/Bynry-360/lib/python3.6/site-packages/django/template/base.py", line 936, in render
    bit = node.render_annotated(context)
  File "/home/admin1/Desktop/Environments/Bynry-360/lib/python3.6/site-packages/django/template/base.py", line 903, in render_annotated
    return self.render(context)
  File "/home/admin1/Desktop/Environments/Bynry-360/lib/python3.6/site-packages/django/template/loader_tags.py", line 150, in render
    return compiled_parent._render(context)
  File "/home/admin1/Desktop/Environments/Bynry-360/lib/python3.6/site-packages/django/template/base.py", line 163, in _render
    return self.nodelist.render(context)
  File "/home/admin1/Desktop/Environments/Bynry-360/lib/python3.6/site-packages/django/template/base.py", line 936, in render
    bit = node.render_annotated(context)
  File "/home/admin1/Desktop/Environments/Bynry-360/lib/python3.6/site-packages/django/template/base.py", line 903, in render_annotated
    return self.render(context)
  File "/home/admin1/Desktop/Environments/Bynry-360/lib/python3.6/site-packages/django/template/loader_tags.py", line 62, in render
    result = block.nodelist.render(context)
  File "/home/admin1/Desktop/Environments/Bynry-360/lib/python3.6/site-packages/django/template/base.py", line 936, in render
    bit = node.render_annotated(context)
  File "/home/admin1/Desktop/Environments/Bynry-360/lib/python3.6/site-packages/django/template/base.py", line 903, in render_annotated
    return self.render(context)
  File "/home/admin1/Desktop/Environments/Bynry-360/lib/python3.6/site-packages/django/template/loader_tags.py", line 62, in render
    result = block.nodelist.render(context)
  File "/home/admin1/Desktop/Environments/Bynry-360/lib/python3.6/site-packages/django/template/base.py", line 936, in render
    bit = node.render_annotated(context)
  File "/home/admin1/Desktop/Environments/Bynry-360/lib/python3.6/site-packages/django/template/base.py", line 903, in render_annotated
    return self.render(context)
  File "/home/admin1/Desktop/Environments/Bynry-360/lib/python3.6/site-packages/django/template/defaulttags.py", line 209, in render
    nodelist.append(node.render_annotated(context))
  File "/home/admin1/Desktop/Environments/Bynry-360/lib/python3.6/site-packages/django/template/base.py", line 903, in render_annotated
    return self.render(context)
  File "/home/admin1/Desktop/Environments/Bynry-360/lib/python3.6/site-packages/django/template/loader_tags.py", line 188, in render
    return template.render(context)
  File "/home/admin1/Desktop/Environments/Bynry-360/lib/python3.6/site-packages/django/template/base.py", line 173, in render
    return self._render(context)
  File "/home/admin1/Desktop/Environments/Bynry-360/lib/python3.6/site-packages/django/template/base.py", line 163, in _render
    return self.nodelist.render(context)
  File "/home/admin1/Desktop/Environments/Bynry-360/lib/python3.6/site-packages/django/template/base.py", line 936, in render
    bit = node.render_annotated(context)
  File "/home/admin1/Desktop/Environments/Bynry-360/lib/python3.6/site-packages/django/template/base.py", line 903, in render_annotated
    return self.render(context)
  File "/home/admin1/Desktop/Environments/Bynry-360/lib/python3.6/site-packages/django/template/defaulttags.py", line 209, in render
    nodelist.append(node.render_annotated(context))
  File "/home/admin1/Desktop/Environments/Bynry-360/lib/python3.6/site-packages/django/template/base.py", line 903, in render_annotated
    return self.render(context)
  File "/home/admin1/Desktop/Environments/Bynry-360/lib/python3.6/site-packages/django/template/defaulttags.py", line 209, in render
    nodelist.append(node.render_annotated(context))
  File "/home/admin1/Desktop/Environments/Bynry-360/lib/python3.6/site-packages/django/template/base.py", line 903, in render_annotated
    return self.render(context)
  File "/home/admin1/Desktop/Environments/Bynry-360/lib/python3.6/site-packages/django/template/defaulttags.py", line 309, in render
    return nodelist.render(context)
  File "/home/admin1/Desktop/Environments/Bynry-360/lib/python3.6/site-packages/django/template/base.py", line 936, in render
    bit = node.render_annotated(context)
  File "/home/admin1/Desktop/Environments/Bynry-360/lib/python3.6/site-packages/django/template/base.py", line 903, in render_annotated
    return self.render(context)
  File "/home/admin1/Desktop/Environments/Bynry-360/lib/python3.6/site-packages/django/template/defaulttags.py", line 309, in render
    return nodelist.render(context)
  File "/home/admin1/Desktop/Environments/Bynry-360/lib/python3.6/site-packages/django/template/base.py", line 936, in render
    bit = node.render_annotated(context)
  File "/home/admin1/Desktop/Environments/Bynry-360/lib/python3.6/site-packages/django/template/base.py", line 903, in render_annotated
    return self.render(context)
  File "/home/admin1/Desktop/Environments/Bynry-360/lib/python3.6/site-packages/django/template/base.py", line 992, in render
    return render_value_in_context(output, context)
  File "/home/admin1/Desktop/Environments/Bynry-360/lib/python3.6/site-packages/django/template/base.py", line 971, in render_value_in_context
    value = str(value)
  File "/home/admin1/Desktop/Environments/Bynry-360/lib/python3.6/site-packages/django/utils/html.py", line 373, in <lambda>
    klass.__str__ = lambda self: mark_safe(klass_str(self))
  File "/home/admin1/Desktop/Environments/Bynry-360/lib/python3.6/site-packages/django/forms/boundfield.py", line 33, in __str__
    return self.as_widget()
  File "/home/admin1/Desktop/Environments/Bynry-360/lib/python3.6/site-packages/django/forms/boundfield.py", line 96, in as_widget
    renderer=self.form.renderer,
  File "/home/admin1/Desktop/Environments/Bynry-360/lib/python3.6/site-packages/django/forms/widgets.py", line 241, in render
    context = self.get_context(name, value, attrs)
  File "/home/admin1/Desktop/Environments/Bynry-360/lib/python3.6/site-packages/django/contrib/admin/widgets.py", line 91, in get_context
    context = super().get_context(name, value, attrs)
  File "/home/admin1/Desktop/Environments/Bynry-360/lib/python3.6/site-packages/django/forms/widgets.py", line 817, in get_context
    value = self.decompress(value)
  File "/home/admin1/Desktop/Environments/Bynry-360/lib/python3.6/site-packages/django/forms/widgets.py", line 905, in decompress
    value = to_current_timezone(value)
  File "/home/admin1/Desktop/Environments/Bynry-360/lib/python3.6/site-packages/django/forms/utils.py", line 176, in to_current_timezone
    if settings.USE_TZ and value is not None and timezone.is_aware(value):
  File "/home/admin1/Desktop/Environments/Bynry-360/lib/python3.6/site-packages/django/utils/timezone.py", line 248, in is_aware
    return value.utcoffset() is not None
AttributeError: 'datetime.date' object has no attribute 'utcoffset'
"GET /admin/registration/registration/3/change/ HTTP/1.1" 500 571278
Not Found: /favicon.ico
"GET /favicon.ico HTTP/1.1" 404 2657
"GET /admin/registration/registration/ HTTP/1.1" 200 4881
"GET /admin/registration/registration/ HTTP/1.1" 200 4881
"GET /admin/registration/ HTTP/1.1" 200 3547
"GET /admin/ HTTP/1.1" 200 41136
/home/admin1/yy/Smart360-app/api/v1/consumer/migrations/0001_initial.py changed, reloading.
Watching for file changes with StatReloader
/home/admin1/yy/Smart360-app/api/api/settings.py changed, reloading.
Watching for file changes with StatReloader
"GET /admin/ HTTP/1.1" 302 0
"GET /admin/login/?next=/admin/ HTTP/1.1" 200 1913
"GET /static/admin/css/login.css HTTP/1.1" 304 0
"POST /admin/login/?next=/admin/ HTTP/1.1" 200 2092
"POST /admin/login/?next=/admin/ HTTP/1.1" 302 0
"GET /admin/ HTTP/1.1" 200 38628
"GET /admin/commonapp/department/ HTTP/1.1" 200 4620
"GET /admin/jsi18n/ HTTP/1.1" 200 3223
"GET /admin/commonapp/department/2/change/ HTTP/1.1" 200 10256
"GET /admin/jsi18n/ HTTP/1.1" 200 3223
"GET /static/admin/css/forms.css HTTP/1.1" 200 8518
"GET /static/admin/js/calendar.js HTTP/1.1" 200 7777
"GET /static/admin/js/admin/DateTimeShortcuts.js HTTP/1.1" 200 20232
"GET /static/admin/css/widgets.css HTTP/1.1" 200 10322
"GET /admin/commonapp/department/ HTTP/1.1" 200 4620
"GET /admin/ HTTP/1.1" 200 38628
"GET /admin/registration/registration/ HTTP/1.1" 200 4881
"GET /admin/jsi18n/ HTTP/1.1" 200 3223
"GET /admin/registration/registration/3/change/ HTTP/1.1" 200 23797
"GET /admin/jsi18n/ HTTP/1.1" 200 3223
"GET /api/v1/registration/list HTTP/1.1" 200 988
/home/admin1/yy/Smart360-app/api/v1/registration/serializers/registration.py changed, reloading.
Watching for file changes with StatReloader
